Workbook

Sheet PPP conversion rate_LCUperID
A1: iso3 | B1: name for match | C1: Economy | D1: c_2021 | E1: c_2022 | F1: c_2023 | G1: c_2024 | H1: c_2025 | I1: c_2026 | J1: c_2027
A2: =VLOOKUP(LOWER(B2),[1]country_name_iso_mapping!$A:$C,3, FALSE) -> AFG | B2: Afghanistan | C2: Afghanistan | D2: =IF(ISNUMBER(Raw_from_worldbank!B6),Raw_from_worldbank!B6, IF(ISNUMBER(SEARCH("k",Raw_from_worldbank!B6)), VALUE(SUBSTITUTE(LOWER(Raw_from_worldbank!B6),"k",""))*1000, NA())) -> 17.3 | E2: =IF(ISNUMBER(Raw_from_worldbank!C6),Raw_from_worldbank!C6, IF(ISNUMBER(SEARCH("k",Raw_from_worldbank!C6)), VALUE(SUBSTITUTE(LOWER(Raw_from_worldbank!C6),"k",""))*1000, NA())) -> 17.7 | F2: =IF(ISNUMBER(Raw_from_worldbank!D6),Raw_from_worldbank!D6, IF(ISNUMBER(SEARCH("k",Raw_from_worldbank!D6)), VALUE(SUBSTITUTE(LOWER(Raw_from_worldbank!D6),"k",""))*1000, NA())) -> #N/A | G2: =IF(ISNUMBER(Raw_from_worldbank!E6),Raw_from_worldbank!E6, IF(ISNUMBER(SEARCH("k",Raw_from_worldbank!E6)), VALUE(SUBSTITUTE(LOWER(Raw_from_worldbank!E6),"k",""))*1000, NA())) -> #N/A | H2: =IF(ISNUMBER(Raw_from_worldbank!F6),Raw_from_worldbank!F6, IF(ISNUMBER(SEARCH("k",Raw_from_worldbank!F6)), VALUE(SUBSTITUTE(LOWER(Raw_from_worldbank!F6),"k",""))*1000, NA())) -> #N/A | I2: =IF(ISNUMBER(Raw_from_worldbank!G6),Raw_from_worldbank!G6, IF(ISNUMBER(SEARCH("k",Raw_from_worldbank!G6)), VALUE(SUBSTITUTE(LOWER(Raw_from_worldbank!G6),"k",""))*1000, NA())) -> #N/A | J2: =IF(ISNUMBER(Raw_from_worldbank!H6),Raw_from_worldbank!H6, IF(ISNUMBER(SEARCH("k",Raw_from_worldbank!H6)), VALUE(SUBSTITUTE(LOWER(Raw_from_worldbank!H6),"k",""))*1000, NA())) -> #N/A
A3: =VLOOKUP(LOWER(B3),[1]country_name_iso_mapping!$A:$C,3, FALSE) -> ALB | B3: Albania | C3: Albania | D3: =IF(ISNUMBER(Raw_from_worldbank!B7),Raw_from_worldbank!B7, IF(ISNUMBER(SEARCH("k",Raw_from_worldbank!B7)), VALUE(SUBSTITUTE(LOWER(Raw_from_worldbank!B7),"k",""))*1000, NA())) -> 40 | E3: =IF(ISNUMBER(Raw_from_worldbank!C7),Raw_from_worldbank!C7, IF(ISNUMBER(SEARCH("k",Raw_from_worldbank!C7)), VALUE(SUBSTITUTE(LOWER(Raw_from_worldbank!C7),"k",""))*1000, NA())) -> 41.1 | F3: =IF(ISNUMBER(Raw_from_worldbank!D7),Raw_from_worldbank!D7, IF(ISNUMBER(SEARCH("k",Raw_from_worldbank!D7)), VALUE(SUBSTITUTE(LOWER(Raw_from_worldbank!D7),"k",""))*1000, NA())) -> 41.4 | G3: =IF(ISNUMBER(Raw_from_worldbank!E7),Raw_from_worldbank!E7, IF(ISNUMBER(SEARCH("k",Raw_from_worldbank!E7)), VALUE(SUBSTITUTE(LOWER(Raw_from_worldbank!E7),"k",""))*1000, NA())) -> 41.8 | H3: =IF(ISNUMBER(Raw_from_worldbank!F7),Raw_from_worldbank!F7, IF(ISNUMBER(SEARCH("k",Raw_from_worldbank!F7)), VALUE(SUBSTITUTE(LOWER(Raw_from_worldbank!F7),"k",""))*1000, NA())) -> 42.3 | I3: =IF(ISNUMBER(Raw_from_worldbank!G7),Raw_from_worldbank!G7, IF(ISNUMBER(SEARCH("k",Raw_from_worldbank!G7)), VALUE(SUBSTITUTE(LOWER(Raw_from_worldbank!G7),"k",""))*1000, NA())) -> 42.7 | J3: =IF(ISNUMBER(Raw_from_worldbank!H7),Raw_from_worldbank!H7, IF(ISNUMBER(SEARCH("k",Raw_from_worldbank!H7)), VALUE(SUBSTITUTE(LOWER(Raw_from_worldbank!H7),"k",""))*1000, NA())) -> 43.2
A4: =VLOOKUP(LOWER(B4),[1]country_name_iso_mapping!$A:$C,3, FALSE) -> DZA | B4: Algeria | C4: Algeria | D4: =IF(ISNUMBER(Raw_from_worldbank!B8),Raw_from_worldbank!B8, IF(ISNUMBER(SEARCH("k",Raw_from_worldbank!B8)), VALUE(SUBSTITUTE(LOWER(Raw_from_worldbank!B8),"k",""))*1000, NA())) -> 41.7 | E4: =IF(ISNUMBER(Raw_from_worldbank!C8),Raw_from_worldbank!C8, IF(ISNUMBER(SEARCH("k",Raw_from_worldbank!C8)), VALUE(SUBSTITUTE(LOWER(Raw_from_worldbank!C8),"k",""))*1000, NA())) -> 47.9 | F4: =IF(ISNUMBER(Raw_from_worldbank!D8),Raw_from_worldbank!D8, IF(ISNUMBER(SEARCH("k",Raw_from_worldbank!D8)), VALUE(SUBSTITUTE(LOWER(Raw_from_worldbank!D8),"k",""))*1000, NA())) -> 46 | G4: =IF(ISNUMBER(Raw_from_worldbank!E8),Raw_from_worldbank!E8, IF(ISNUMBER(SEARCH("k",Raw_from_worldbank!E8)), VALUE(SUBSTITUTE(LOWER(Raw_from_worldbank!E8),"k",""))*1000, NA())) -> 47.8 | H4: =IF(ISNUMBER(Raw_from_worldbank!F8),Raw_from_worldbank!F8, IF(ISNUMBER(SEARCH("k",Raw_from_worldbank!F8)), VALUE(SUBSTITUTE(LOWER(Raw_from_worldbank!F8),"k",""))*1000, NA())) -> 49.8 | I4: =IF(ISNUMBER(Raw_from_worldbank!G8),Raw_from_worldbank!G8, IF(ISNUMBER(SEARCH("k",Raw_from_worldbank!G8)), VALUE(SUBSTITUTE(LOWER(Raw_from_worldbank!G8),"k",""))*1000, NA())) -> 51.8 | J4: =IF(ISNUMBER(Raw_from_worldbank!H8),Raw_from_worldbank!H8, IF(ISNUMBER(SEARCH("k",Raw_from_worldbank!H8)), VALUE(SUBSTITUTE(LOWER(Raw_from_worldbank!H8),"k",""))*1000, NA())) -> 53.6
A5: =VLOOKUP(LOWER(B5),[1]country_name_iso_mapping!$A:$C,3, FALSE) -> AND | B5: Andorra | C5: Andorra | D5: =IF(ISNUMBER(Raw_from_worldbank!B9),Raw_from_worldbank!B9, IF(ISNUMBER(SEARCH("k",Raw_from_worldbank!B9)), VALUE(SUBSTITUTE(LOWER(Raw_from_worldbank!B9),"k",""))*1000, NA())) -> 0.61 | E5: =IF(ISNUMBER(Raw_from_worldbank!C9),Raw_from_worldbank!C9, IF(ISNUMBER(SEARCH("k",Raw_from_worldbank!C9)), VALUE(SUBSTITUTE(LOWER(Raw_from_worldbank!C9),"k",""))*1000, NA())) -> 0.59 | F5: =IF(ISNUMBER(Raw_from_worldbank!D9),Raw_from_worldbank!D9, IF(ISNUMBER(SEARCH("k",Raw_from_worldbank!D9)), VALUE(SUBSTITUTE(LOWER(Raw_from_worldbank!D9),"k",""))*1000, NA())) -> 0.6 | G5: =IF(ISNUMBER(Raw_from_worldbank!E9),Raw_from_worldbank!E9, IF(ISNUMBER(SEARCH("k",Raw_from_worldbank!E9)), VALUE(SUBSTITUTE(LOWER(Raw_from_worldbank!E9),"k",""))*1000, NA())) -> 0.6 | H5: =IF(ISNUMBER(Raw_from_worldbank!F9),Raw_from_worldbank!F9, IF(ISNUMBER(SEARCH("k",Raw_from_worldbank!F9)), VALUE(SUBSTITUTE(LOWER(Raw_from_worldbank!F9),"k",""))*1000, NA())) -> 0.61 | I5: =IF(ISNUMBER(Raw_from_worldbank!G9),Raw_from_worldbank!G9, IF(ISNUMBER(SEARCH("k",Raw_from_worldbank!G9)), VALUE(SUBSTITUTE(LOWER(Raw_from_worldbank!G9),"k",""))*1000, NA())) -> 0.6 | J5: =IF(ISNUMBER(Raw_from_worldbank!H9),Raw_from_worldbank!H9, IF(ISNUMBER(SEARCH("k",Raw_from_worldbank!H9)), VALUE(SUBSTITUTE(LOWER(Raw_from_worldbank!H9),"k",""))*1000, NA())) -> 0.6
A6: =VLOOKUP(LOWER(B6),[1]country_name_iso_mapping!$A:$C,3, FALSE) -> AGO | B6: Angola | C6: Angola | D6: =IF(ISNUMBER(Raw_from_worldbank!B10),Raw_from_worldbank!B10, IF(ISNUMBER(SEARCH("k",Raw_from_worldbank!B10)), VALUE(SUBSTITUTE(LOWER(Raw_from_worldbank!B10),"k",""))*1000, NA())) -> 210.4 | E6: =IF(ISNUMBER(Raw_from_worldbank!C10),Raw_from_worldbank!C10, IF(ISNUMBER(SEARCH("k",Raw_from_worldbank!C10)), VALUE(SUBSTITUTE(LOWER(Raw_from_worldbank!C10),"k",""))*1000, NA())) -> 229.1 | F6: =IF(ISNUMBER(Raw_from_worldbank!D10),Raw_from_worldbank!D10, IF(ISNUMBER(SEARCH("k",Raw_from_worldbank!D10)), VALUE(SUBSTITUTE(LOWER(Raw_from_worldbank!D10),"k",""))*1000, NA())) -> 250.7 | G6: =IF(ISNUMBER(Raw_from_worldbank!E10),Raw_from_worldbank!E10, IF(ISNUMBER(SEARCH("k",Raw_from_worldbank!E10)), VALUE(SUBSTITUTE(LOWER(Raw_from_worldbank!E10),"k",""))*1000, NA())) -> 304.5 | H6: =IF(ISNUMBER(Raw_from_worldbank!F10),Raw_from_worldbank!F10, IF(ISNUMBER(SEARCH("k",Raw_from_worldbank!F10)), VALUE(SUBSTITUTE(LOWER(Raw_from_worldbank!F10),"k",""))*1000, NA())) -> 332.3 | I6: =IF(ISNUMBER(Raw_from_worldbank!G10),Raw_from_worldbank!G10, IF(ISNUMBER(SEARCH("k",Raw_from_worldbank!G10)), VALUE(SUBSTITUTE(LOWER(Raw_from_worldbank!G10),"k",""))*1000, NA())) -> 347.1 | J6: =IF(ISNUMBER(Raw_from_worldbank!H10),Raw_from_worldbank!H10, IF(ISNUMBER(SEARCH("k",Raw_from_worldbank!H10)), VALUE(SUBSTITUTE(LOWER(Raw_from_worldbank!H10),"k",""))*1000, NA())) -> 362.5
A7: =VLOOKUP(LOWER(B7),[1]country_name_iso_mapping!$A:$C,3, FALSE) -> ATG | B7: Antigua and Barbuda | C7: Antigua and Barbuda | D7: =IF(ISNUMBER(Raw_from_worldbank!B11),Raw_from_worldbank!B11, IF(ISNUMBER(SEARCH("k",Raw_from_worldbank!B11)), VALUE(SUBSTITUTE(LOWER(Raw_from_worldbank!B11),"k",""))*1000, NA())) -> 2.1 | E7: =IF(ISNUMBER(Raw_from_worldbank!C11),Raw_from_worldbank!C11, IF(ISNUMBER(SEARCH("k",Raw_from_worldbank!C11)), VALUE(SUBSTITUTE(LOWER(Raw_from_worldbank!C11),"k",""))*1000, NA())) -> 2 | F7: =IF(ISNUMBER(Raw_from_worldbank!D11),Raw_from_worldbank!D11, IF(ISNUMBER(SEARCH("k",Raw_from_worldbank!D11)), VALUE(SUBSTITUTE(LOWER(Raw_from_worldbank!D11),"k",""))*1000, NA())) -> 2 | G7: =IF(ISNUMBER(Raw_from_worldbank!E11),Raw_from_worldbank!E11, IF(ISNUMBER(SEARCH("k",Raw_from_worldbank!E11)), VALUE(SUBSTITUTE(LOWER(Raw_from_worldbank!E11),"k",""))*1000, NA())) -> 2 | H7: =IF(ISNUMBER(Raw_from_worldbank!F11),Raw_from_worldbank!F11, IF(ISNUMBER(SEARCH("k",Raw_from_worldbank!F11)), VALUE(SUBSTITUTE(LOWER(Raw_from_worldbank!F11),"k",""))*1000, NA())) -> 2 | I7: =IF(ISNUMBER(Raw_from_worldbank!G11),Raw_from_worldbank!G11, IF(ISNUMBER(SEARCH("k",Raw_from_worldbank!G11)), VALUE(SUBSTITUTE(LOWER(Raw_from_worldbank!G11),"k",""))*1000, NA())) -> 2 | J7: =IF(ISNUMBER(Raw_from_worldbank!H11),Raw_from_worldbank!H11, IF(ISNUMBER(SEARCH("k",Raw_from_worldbank!H11)), VALUE(SUBSTITUTE(LOWER(Raw_from_worldbank!H11),"k",""))*1000, NA())) -> 2
A8: =VLOOKUP(LOWER(B8),[1]country_name_iso_mapping!$A:$C,3, FALSE) -> ARG | B8: Argentina | C8: Argentina | D8: =IF(ISNUMBER(Raw_from_worldbank!B12),Raw_from_worldbank!B12, IF(ISNUMBER(SEARCH("k",Raw_from_worldbank!B12)), VALUE(SUBSTITUTE(LOWER(Raw_from_worldbank!B12),"k",""))*1000, NA())) -> 42.5 | E8: =IF(ISNUMBER(Raw_from_worldbank!C12),Raw_from_worldbank!C12, IF(ISNUMBER(SEARCH("k",Raw_from_worldbank!C12)), VALUE(SUBSTITUTE(LOWER(Raw_from_worldbank!C12),"k",""))*1000, NA())) -> 67.3 | F8: =IF(ISNUMBER(Raw_from_worldbank!D12),Raw_from_worldbank!D12, IF(ISNUMBER(SEARCH("k",Raw_from_worldbank!D12)), VALUE(SUBSTITUTE(LOWER(Raw_from_worldbank!D12),"k",""))*1000, NA())) -> 154 | G8: =IF(ISNUMBER(Raw_from_worldbank!E12),Raw_from_worldbank!E12, IF(ISNUMBER(SEARCH("k",Raw_from_worldbank!E12)), VALUE(SUBSTITUTE(LOWER(Raw_from_worldbank!E12),"k",""))*1000, NA())) -> 528.7 | H8: =IF(ISNUMBER(Raw_from_worldbank!F12),Raw_from_worldbank!F12, IF(ISNUMBER(SEARCH("k",Raw_from_worldbank!F12)), VALUE(SUBSTITUTE(LOWER(Raw_from_worldbank!F12),"k",""))*1000, NA())) -> 826.5 | I8: =IF(ISNUMBER(Raw_from_worldbank!G12),Raw_from_worldbank!G12, IF(ISNUMBER(SEARCH("k",Raw_from_worldbank!G12)), VALUE(SUBSTITUTE(LOWER(Raw_from_worldbank!G12),"k",""))*1000, NA())) -> 1100 | J8: =IF(ISNUMBER(Raw_from_worldbank!H12),Raw_from_worldbank!H12, IF(ISNUMBER(SEARCH("k",Raw_from_worldbank!H12)), VALUE(SUBSTITUTE(LOWER(Raw_from_worldbank!H12),"k",""))*1000, NA())) -> 1200
A9: =VLOOKUP(LOWER(B9),[1]country_name_iso_mapping!$A:$C,3, FALSE) -> ARM | B9: Armenia | C9: Armenia | D9: =IF(ISNUMBER(Raw_from_worldbank!B13),Raw_from_worldbank!B13, IF(ISNUMBER(SEARCH("k",Raw_from_worldbank!B13)), VALUE(SUBSTITUTE(LOWER(Raw_from_worldbank!B13),"k",""))*1000, NA())) -> 160 | E9: =IF(ISNUMBER(Raw_from_worldbank!C13),Raw_from_worldbank!C13, IF(ISNUMBER(SEARCH("k",Raw_from_worldbank!C13)), VALUE(SUBSTITUTE(LOWER(Raw_from_worldbank!C13),"k",""))*1000, NA())) -> 161.4 | F9: =IF(ISNUMBER(Raw_from_worldbank!D13),Raw_from_worldbank!D13, IF(ISNUMBER(SEARCH("k",Raw_from_worldbank!D13)), VALUE(SUBSTITUTE(LOWER(Raw_from_worldbank!D13),"k",""))*1000, NA())) -> 160.1 | G9: =IF(ISNUMBER(Raw_from_worldbank!E13),Raw_from_worldbank!E13, IF(ISNUMBER(SEARCH("k",Raw_from_worldbank!E13)), VALUE(SUBSTITUTE(LOWER(Raw_from_worldbank!E13),"k",""))*1000, NA())) -> 162.6 | H9: =IF(ISNUMBER(Raw_from_worldbank!F13),Raw_from_worldbank!F13, IF(ISNUMBER(SEARCH("k",Raw_from_worldbank!F13)), VALUE(SUBSTITUTE(LOWER(Raw_from_worldbank!F13),"k",""))*1000, NA())) -> 166.2 | I9: =IF(ISNUMBER(Raw_from_worldbank!G13),Raw_from_worldbank!G13, IF(ISNUMBER(SEARCH("k",Raw_from_worldbank!G13)), VALUE(SUBSTITUTE(LOWER(Raw_from_worldbank!G13),"k",""))*1000, NA())) -> 169.5 | J9: =IF(ISNUMBER(Raw_from_worldbank!H13),Raw_from_worldbank!H13, IF(ISNUMBER(SEARCH("k",Raw_from_worldbank!H13)), VALUE(SUBSTITUTE(LOWER(Raw_from_worldbank!H13),"k",""))*1000, NA())) -> 172.9
A10: =VLOOKUP(LOWER(B10),[1]country_name_iso_mapping!$A:$C,3, FALSE) -> ABW | B10: Aruba | C10: Aruba | D10: =IF(ISNUMBER(Raw_from_worldbank!B14),Raw_from_worldbank!B14, IF(ISNUMBER(SEARCH("k",Raw_from_worldbank!B14)), VALUE(SUBSTITUTE(LOWER(Raw_from_worldbank!B14),"k",""))*1000, NA())) -> 1.3 | E10: =IF(ISNUMBER(Raw_from_worldbank!C14),Raw_from_worldbank!C14, IF(ISNUMBER(SEARCH("k",Raw_from_worldbank!C14)), VALUE(SUBSTITUTE(LOWER(Raw_from_worldbank!C14),"k",""))*1000, NA())) -> 1.2 | F10: =IF(ISNUMBER(Raw_from_worldbank!D14),Raw_from_worldbank!D14, IF(ISNUMBER(SEARCH("k",Raw_from_worldbank!D14)), VALUE(SUBSTITUTE(LOWER(Raw_from_worldbank!D14),"k",""))*1000, NA())) -> 1.2 | G10: =IF(ISNUMBER(Raw_from_worldbank!E14),Raw_from_worldbank!E14, IF(ISNUMBER(SEARCH("k",Raw_from_worldbank!E14)), VALUE(SUBSTITUTE(LOWER(Raw_from_worldbank!E14),"k",""))*1000, NA())) -> 1.2 | H10: =IF(ISNUMBER(Raw_from_worldbank!F14),Raw_from_worldbank!F14, IF(ISNUMBER(SEARCH("k",Raw_from_worldbank!F14)), VALUE(SUBSTITUTE(LOWER(Raw_from_worldbank!F14),"k",""))*1000, NA())) -> 1.2 | I10: =IF(ISNUMBER(Raw_from_worldbank!G14),Raw_from_worldbank!G14, IF(ISNUMBER(SEARCH("k",Raw_from_worldbank!G14)), VALUE(SUBSTITUTE(LOWER(Raw_from_worldbank!G14),"k",""))*1000, NA())) -> 1.2 | J10: =IF(ISNUMBER(Raw_from_worldbank!H14),Raw_from_worldbank!H14, IF(ISNUMBER(SEARCH("k",Raw_from_worldbank!H14)), VALUE(SUBSTITUTE(LOWER(Raw_from_worldbank!H14),"k",""))*1000, NA())) -> 1.2
A11: =VLOOKUP(LOWER(B11),[1]country_name_iso_mapping!$A:$C,3, FALSE) -> AUS | B11: Australia | C11: Australia | D11: =IF(ISNUMBER(Raw_from_worldbank!B15),Raw_from_worldbank!B15, IF(ISNUMBER(SEARCH("k",Raw_from_worldbank!B15)), VALUE(SUBSTITUTE(LOWER(Raw_from_worldbank!B15),"k",""))*1000, NA())) -> 1.5 | E11: =IF(ISNUMBER(Raw_from_worldbank!C15),Raw_from_worldbank!C15, IF(ISNUMBER(SEARCH("k",Raw_from_worldbank!C15)), VALUE(SUBSTITUTE(LOWER(Raw_from_worldbank!C15),"k",""))*1000, NA())) -> 1.5 | F11: =IF(ISNUMBER(Raw_from_worldbank!D15),Raw_from_worldbank!D15, IF(ISNUMBER(SEARCH("k",Raw_from_worldbank!D15)), VALUE(SUBSTITUTE(LOWER(Raw_from_worldbank!D15),"k",""))*1000, NA())) -> 1.5 | G11: =IF(ISNUMBER(Raw_from_worldbank!E15),Raw_from_worldbank!E15, IF(ISNUMBER(SEARCH("k",Raw_from_worldbank!E15)), VALUE(SUBSTITUTE(LOWER(Raw_from_worldbank!E15),"k",""))*1000, NA())) -> 1.5 | H11: =IF(ISNUMBER(Raw_from_worldbank!F15),Raw_from_worldbank!F15, IF(ISNUMBER(SEARCH("k",Raw_from_worldbank!F15)), VALUE(SUBSTITUTE(LOWER(Raw_from_worldbank!F15),"k",""))*1000, NA())) -> 1.6 | I11: =IF(ISNUMBER(Raw_from_worldbank!G15),Raw_from_worldbank!G15, IF(ISNUMBER(SEARCH("k",Raw_from_worldbank!G15)), VALUE(SUBSTITUTE(LOWER(Raw_from_worldbank!G15),"k",""))*1000, NA())) -> 1.6 | J11: =IF(ISNUMBER(Raw_from_worldbank!H15),Raw_from_worldbank!H15, IF(ISNUMBER(SEARCH("k",Raw_from_worldbank!H15)), VALUE(SUBSTITUTE(LOWER(Raw_from_worldbank!H15),"k",""))*1000, NA())) -> 1.6
A12: =VLOOKUP(LOWER(B12),[1]country_name_iso_mapping!$A:$C,3, FALSE) -> AUT | B12: Austria | C12: Austria | D12: =IF(ISNUMBER(Raw_from_worldbank!B16),Raw_from_worldbank!B16, IF(ISNUMBER(SEARCH("k",Raw_from_worldbank!B16)), VALUE(SUBSTITUTE(LOWER(Raw_from_worldbank!B16),"k",""))*1000, NA())) -> 0.76 | E12: =IF(ISNUMBER(Raw_from_worldbank!C16),Raw_from_worldbank!C16, IF(ISNUMBER(SEARCH("k",Raw_from_worldbank!C16)), VALUE(SUBSTITUTE(LOWER(Raw_from_worldbank!C16),"k",""))*1000, NA())) -> 0.75 | F12: =IF(ISNUMBER(Raw_from_worldbank!D16),Raw_from_worldbank!D16, IF(ISNUMBER(SEARCH("k",Raw_from_worldbank!D16)), VALUE(SUBSTITUTE(LOWER(Raw_from_worldbank!D16),"k",""))*1000, NA())) -> 0.78 | G12: =IF(ISNUMBER(Raw_from_worldbank!E16),Raw_from_worldbank!E16, IF(ISNUMBER(SEARCH("k",Raw_from_worldbank!E16)), VALUE(SUBSTITUTE(LOWER(Raw_from_worldbank!E16),"k",""))*1000, NA())) -> 0.79 | H12: =IF(ISNUMBER(Raw_from_worldbank!F16),Raw_from_worldbank!F16, IF(ISNUMBER(SEARCH("k",Raw_from_worldbank!F16)), VALUE(SUBSTITUTE(LOWER(Raw_from_worldbank!F16),"k",""))*1000, NA())) -> 0.8 | I12: =IF(ISNUMBER(Raw_from_worldbank!G16),Raw_from_worldbank!G16, IF(ISNUMBER(SEARCH("k",Raw_from_worldbank!G16)), VALUE(SUBSTITUTE(LOWER(Raw_from_worldbank!G16),"k",""))*1000, NA())) -> 0.8 | J12: =IF(ISNUMBER(Raw_from_worldbank!H16),Raw_from_worldbank!H16, IF(ISNUMBER(SEARCH("k",Raw_from_worldbank!H16)), VALUE(SUBSTITUTE(LOWER(Raw_from_worldbank!H16),"k",""))*1000, NA())) -> 0.8
A13: =VLOOKUP(LOWER(B13),[1]country_name_iso_mapping!$A:$C,3, FALSE) -> AZE | B13: Azerbaijan | C13: Azerbaijan | D13: =IF(ISNUMBER(Raw_from_worldbank!B17),Raw_from_worldbank!B17, IF(ISNUMBER(SEARCH("k",Raw_from_worldbank!B17)), VALUE(SUBSTITUTE(LOWER(Raw_from_worldbank!B17),"k",""))*1000, NA())) -> 0.58 | E13: =IF(ISNUMBER(Raw_from_worldbank!C17),Raw_from_worldbank!C17, IF(ISNUMBER(SEARCH("k",Raw_from_worldbank!C17)), VALUE(SUBSTITUTE(LOWER(Raw_from_worldbank!C17),"k",""))*1000, NA())) -> 0.74 | F13: =IF(ISNUMBER(Raw_from_worldbank!D17),Raw_from_worldbank!D17, IF(ISNUMBER(SEARCH("k",Raw_from_worldbank!D17)), VALUE(SUBSTITUTE(LOWER(Raw_from_worldbank!D17),"k",""))*1000, NA())) -> 0.69 | G13: =IF(ISNUMBER(Raw_from_worldbank!E17),Raw_from_worldbank!E17, IF(ISNUMBER(SEARCH("k",Raw_from_worldbank!E17)), VALUE(SUBSTITUTE(LOWER(Raw_from_worldbank!E17),"k",""))*1000, NA())) -> 0.67 | H13: =IF(ISNUMBER(Raw_from_worldbank!F17),Raw_from_worldbank!F17, IF(ISNUMBER(SEARCH("k",Raw_from_worldbank!F17)), VALUE(SUBSTITUTE(LOWER(Raw_from_worldbank!F17),"k",""))*1000, NA())) -> 0.67 | I13: =IF(ISNUMBER(Raw_from_worldbank!G17),Raw_from_worldbank!G17, IF(ISNUMBER(SEARCH("k",Raw_from_worldbank!G17)), VALUE(SUBSTITUTE(LOWER(Raw_from_worldbank!G17),"k",""))*1000, NA())) -> 0.67 | J13: =IF(ISNUMBER(Raw_from_worldbank!H17),Raw_from_worldbank!H17, IF(ISNUMBER(SEARCH("k",Raw_from_worldbank!H17)), VALUE(SUBSTITUTE(LOWER(Raw_from_worldbank!H17),"k",""))*1000, NA())) -> 0.67
... A197: =VLOOKUP(LOWER(B197),[1]country_name_iso_mapping!$A:$C,3, FALSE) -> ZWE | B197: Zimbabwe | C197: Zimbabwe | D197: =IF(ISNUMBER(Raw_from_worldbank!B201),Raw_from_worldbank!B201, IF(ISNUMBER(SEARCH("k",Raw_from_worldbank!B201)), VALUE(SUBSTITUTE(LOWER(Raw_from_worldbank!B201),"k",""))*1000, NA())) -> 85.5 | E197: =IF(ISNUMBER(Raw_from_worldbank!C201),Raw_from_worldbank!C201, IF(ISNUMBER(SEARCH("k",Raw_from_worldbank!C201)), VALUE(SUBSTITUTE(LOWER(Raw_from_worldbank!C201),"k",""))*1000, NA())) -> 291.4 | F197: =IF(ISNUMBER(Raw_from_worldbank!D201),Raw_from_worldbank!D201, IF(ISNUMBER(SEARCH("k",Raw_from_worldbank!D201)), VALUE(SUBSTITUTE(LOWER(Raw_from_worldbank!D201),"k",""))*1000, NA())) -> 2600 | G197: =IF(ISNUMBER(Raw_from_worldbank!E201),Raw_from_worldbank!E201, IF(ISNUMBER(SEARCH("k",Raw_from_worldbank!E201)), VALUE(SUBSTITUTE(LOWER(Raw_from_worldbank!E201),"k",""))*1000, NA())) -> 16600 | H197: =IF(ISNUMBER(Raw_from_worldbank!F201),Raw_from_worldbank!F201, IF(ISNUMBER(SEARCH("k",Raw_from_worldbank!F201)), VALUE(SUBSTITUTE(LOWER(Raw_from_worldbank!F201),"k",""))*1000, NA())) -> 106500 | I197: =IF(ISNUMBER(Raw_from_worldbank!G201),Raw_from_worldbank!G201, IF(ISNUMBER(SEARCH("k",Raw_from_worldbank!G201)), VALUE(SUBSTITUTE(LOWER(Raw_from_worldbank!G201),"k",""))*1000, NA())) -> 639300 | J197: =IF(ISNUMBER(Raw_from_worldbank!H201),Raw_from_worldbank!H201, IF(ISNUMBER(SEARCH("k",Raw_from_worldbank!H201)), VALUE(SUBSTITUTE(LOWER(Raw_from_worldbank!H201),"k",""))*1000, NA())) -> #N/A

Sheet Raw_from_worldbank
A1: Implied PPP conversion rate, National currency per current international dollar
A2: 2021-2027, Domestic currency per PPP dollars
A5: Economy | B5: Value (2021) | C5: Value (2022) | D5: Value (2023) | E5: Value (2024) | F5: Value (2025) | G5: Value (2026) | H5: Value (2027)
A6: Afghanistan | B6: 17.3 | C6: 17.7 | D6: -- | E6: -- | F6: -- | G6: -- | H6: --
A7: Albania | B7: 40 | C7: 41.1 | D7: 41.4 | E7: 41.8 | F7: 42.3 | G7: 42.7 | H7: 43.2
A8: Algeria | B8: 41.7 | C8: 47.9 | D8: 46 | E8: 47.8 | F8: 49.8 | G8: 51.8 | H8: 53.6
A9: Andorra | B9: 0.61 | C9: 0.59 | D9: 0.6 | E9: 0.6 | F9: 0.61 | G9: 0.6 | H9: 0.6
A10: Angola | B10: 210.4 | C10: 229.1 | D10: 250.7 | E10: 304.5 | F10: 332.3 | G10: 347.1 | H10: 362.5
A11: Antigua and Barbuda | B11: 2.1 | C11: 2 | D11: 2 | E11: 2 | F11: 2 | G11: 2 | H11: 2
A12: Argentina | B12: 42.5 | C12: 67.3 | D12: 154 | E12: 528.7 | F12: 826.5 | G12: 1.1k | H12: 1.2k
A13: Armenia | B13: 160 | C13: 161.4 | D13: 160.1 | E13: 162.6 | F13: 166.2 | G13: 169.5 | H13: 172.9
A14: Aruba | B14: 1.3 | C14: 1.2 | D14: 1.2 | E14: 1.2 | F14: 1.2 | G14: 1.2 | H14: 1.2
A15: Australia | B15: 1.5 | C15: 1.5 | D15: 1.5 | E15: 1.5 | F15: 1.6 | G15: 1.6 | H15: 1.6
A16: Austria | B16: 0.76 | C16: 0.75 | D16: 0.78 | E16: 0.79 | F16: 0.8 | G16: 0.8 | H16: 0.8
A17: Azerbaijan | B17: 0.58 | C17: 0.74 | D17: 0.69 | E17: 0.67 | F17: 0.67 | G17: 0.67 | H17: 0.67
A18: Bahamas, The | B18: 0.84 | C18: 0.77 | D18: 0.76 | E18: 0.76 | F18: 0.76 | G18: 0.76 | H18: 0.76
A19: Bahrain | B19: 0.18 | C19: 0.18 | D19: 0.17 | E19: 0.17 | F19: 0.17 | G19: 0.17 | H19: 0.17
A20: Bangladesh | B20: 31.9 | C20: 31.3 | D20: 32 | E20: 32.9 | F20: 34.1 | G20: 35.4 | H20: 36.7
A21: Barbados | B21: 2.3 | C21: 2.2 | D21: 2.3 | E21: 2.3 | F21: 2.3 | G21: 2.3 | H21: 2.4
A22: Belarus | B22: 0.85 | C22: 0.92 | D22: 0.97 | E22: 0.97 | F22: 1 | G22: 1.1 | H22: 1.1
A23: Belgium | B23: 0.76 | C23: 0.75 | D23: 0.75 | E23: 0.76 | F23: 0.76 | G23: 0.76 | H23: 0.76
A24: Belize | B24: 1.2 | C24: 1.3 | D24: 1.3 | E24: 1.3 | F24: 1.3 | G24: 1.3 | H24: 1.3
... A33: Burkina Faso | B33: 205.6 | C33: 203.9 | D33: 199.5 | E33: 199.1 | F33: 199.9 | G33: 200.4 | H33: 200.9
A34: Burundi | B34: 669.1 | C34: 739.7 | D34: 950 | E34: 1.1k | F34: 1.3k | G34: 1.5k | H34: 1.6k
A35: Cabo Verde | B35: 45.2 | C35: 45.5 | D35: 45.8 | E35: 45.7 | F35: 45.8 | G35: 45.8 | H35: 45.9
A36: Cambodia | B36: 1.4k | C36: 1.4k | D36: 1.4k | E36: 1.4k | F36: 1.4k | G36: 1.4k | H36: 1.4k
A37: Cameroon | B37: 226.1 | C37: 224.6 | D37: 223.4 | E37: 225.3 | F37: 229.8 | G37: 232 | H37: 233.4
A38: Canada | B38: 1.2 | C38: 1.2 | D38: 1.2 | E38: 1.2 | F38: 1.2 | G38: 1.2 | H38: 1.2
A39: Central African Republic | B39: 284.2 | C39: 282.4 | D39: 281.9 | E39: 291.6 | F39: 299.4 | G39: 305 | H39: 308.8
A40: Chad | B40: 231.6 | C40: 241.2 | D40: 231.5 | E40: 232.7 | F40: 232.4 | G40: 234.7 | H40: 237.5
A41: Chile | B41: 455.9 | C41: 459.6 | D41: 472.7 | E41: 475.3 | F41: 481 | G41: 486.2 | H41: 491.4
A42: China | B42: 4.2 | C42: 4 | D42: 3.8 | E42: 3.8 | F42: 3.8 | G42: 3.8 | H42: 3.8
A43: Colombia | B43: 1.4k | C43: 1.5k | D43: 1.6k | E43: 1.6k | F43: 1.6k | G43: 1.7k | H43: 1.7k
A44: Comoros | B44: 181.2 | C44: 178.2 | D44: 177 | E44: 176.3 | F44: 176.9 | G44: 177.2 | H44: 177.4
A45: Congo, Dem. Rep. | B45: 992.7 | C45: 974.3 | D45: 1.1k | E45: 1.3k | F45: 1.3k | G45: 1.4k | H45: 1.5k
A46: Congo, Rep. | B46: 311.6 | C46: 335.1 | D46: 312.8 | E46: 311.6 | F46: 310.6 | G46: 310 | H46: 310.4
A47: Costa Rica | B47: 344.2 | C47: 341.8 | D47: 329.4 | E47: 325.7 | F47: 330.3 | G47: 334.5 | H47: 338.8
A48: Cote d'Ivoire | B48: 252.7 | C48: 245.4 | D48: 241.1 | E48: 241 | F48: 241.5 | G48: 241.8 | H48: 242.1
A49: Croatia | B49: 0.43 | C49: 0.44 | D49: 0.46 | E49: 0.47 | F49: 0.47 | G49: 0.47 | H49: 0.47
A50: Cyprus | B50: 0.58 | C50: 0.57 | D50: 0.58 | E50: 0.59 | F50: 0.59 | G50: 0.59 | H50: 0.6
...
