Workbook

Sheet LCUperUSD
A1: Country Name | B1: Country Code | C1: lcu_per_usd_clean | D1: data year
A2: Aruba | B2: ABW | C2: {=ROUND(_xlfn.LET( _xlpm.r, INDEX('Raw_from_worldbank_PA.NUS.FCRF'!$C$2:$BR$272, MATCH(B2,'Raw_from_worldbank_PA.NUS.FCRF'!$B$2:$B$272,0),0), LOOKUP(2,1/(_xlpm.r<>""),_xlpm.r) ),2)} -> 1.79 | D2: {=_xlfn.LET( _xlpm.r, INDEX('Raw_from_worldbank_PA.NUS.FCRF'!$C$2:$BR$272, MATCH(B2,'Raw_from_worldbank_PA.NUS.FCRF'!$B$2:$B$272,0),0), _xlpm.yrs, 'Raw_from_worldbank_PA.NUS.FCRF'!$C$1:$BR$1, LOOKUP(2,1/(_xlpm.r<>""),_xlpm.yrs) )} -> 2024
A3: Afghanistan | B3: AFG | C3: {=ROUND(_xlfn.LET( _xlpm.r, INDEX('Raw_from_worldbank_PA.NUS.FCRF'!$C$2:$BR$272, MATCH(B3,'Raw_from_worldbank_PA.NUS.FCRF'!$B$2:$B$272,0),0), LOOKUP(2,1/(_xlpm.r<>""),_xlpm.r) ),2)} -> 76.81 | D3: {=_xlfn.LET( _xlpm.r, INDEX('Raw_from_worldbank_PA.NUS.FCRF'!$C$2:$BR$272, MATCH(B3,'Raw_from_worldbank_PA.NUS.FCRF'!$B$2:$B$272,0),0), _xlpm.yrs, 'Raw_from_worldbank_PA.NUS.FCRF'!$C$1:$BR$1, LOOKUP(2,1/(_xlpm.r<>""),_xlpm.yrs) )} -> 2020
A4: Angola | B4: AGO | C4: {=ROUND(_xlfn.LET( _xlpm.r, INDEX('Raw_from_worldbank_PA.NUS.FCRF'!$C$2:$BR$272, MATCH(B4,'Raw_from_worldbank_PA.NUS.FCRF'!$B$2:$B$272,0),0), LOOKUP(2,1/(_xlpm.r<>""),_xlpm.r) ),2)} -> 869.85 | D4: {=_xlfn.LET( _xlpm.r, INDEX('Raw_from_worldbank_PA.NUS.FCRF'!$C$2:$BR$272, MATCH(B4,'Raw_from_worldbank_PA.NUS.FCRF'!$B$2:$B$272,0),0), _xlpm.yrs, 'Raw_from_worldbank_PA.NUS.FCRF'!$C$1:$BR$1, LOOKUP(2,1/(_xlpm.r<>""),_xlpm.yrs) )} -> 2024
A5: Albania | B5: ALB | C5: {=ROUND(_xlfn.LET( _xlpm.r, INDEX('Raw_from_worldbank_PA.NUS.FCRF'!$C$2:$BR$272, MATCH(B5,'Raw_from_worldbank_PA.NUS.FCRF'!$B$2:$B$272,0),0), LOOKUP(2,1/(_xlpm.r<>""),_xlpm.r) ),2)} -> 93.12 | D5: {=_xlfn.LET( _xlpm.r, INDEX('Raw_from_worldbank_PA.NUS.FCRF'!$C$2:$BR$272, MATCH(B5,'Raw_from_worldbank_PA.NUS.FCRF'!$B$2:$B$272,0),0), _xlpm.yrs, 'Raw_from_worldbank_PA.NUS.FCRF'!$C$1:$BR$1, LOOKUP(2,1/(_xlpm.r<>""),_xlpm.yrs) )} -> 2024
A6: Andorra | B6: AND | C6: {=ROUND(_xlfn.LET( _xlpm.r, INDEX('Raw_from_worldbank_PA.NUS.FCRF'!$C$2:$BR$272, MATCH(B6,'Raw_from_worldbank_PA.NUS.FCRF'!$B$2:$B$272,0),0), LOOKUP(2,1/(_xlpm.r<>""),_xlpm.r) ),2)} -> 0.92 | D6: {=_xlfn.LET( _xlpm.r, INDEX('Raw_from_worldbank_PA.NUS.FCRF'!$C$2:$BR$272, MATCH(B6,'Raw_from_worldbank_PA.NUS.FCRF'!$B$2:$B$272,0),0), _xlpm.yrs, 'Raw_from_worldbank_PA.NUS.FCRF'!$C$1:$BR$1, LOOKUP(2,1/(_xlpm.r<>""),_xlpm.yrs) )} -> 2024
A7: United Arab Emirates | B7: ARE | C7: {=ROUND(_xlfn.LET( _xlpm.r, INDEX('Raw_from_worldbank_PA.NUS.FCRF'!$C$2:$BR$272, MATCH(B7,'Raw_from_worldbank_PA.NUS.FCRF'!$B$2:$B$272,0),0), LOOKUP(2,1/(_xlpm.r<>""),_xlpm.r) ),2)} -> 3.67 | D7: {=_xlfn.LET( _xlpm.r, INDEX('Raw_from_worldbank_PA.NUS.FCRF'!$C$2:$BR$272, MATCH(B7,'Raw_from_worldbank_PA.NUS.FCRF'!$B$2:$B$272,0),0), _xlpm.yrs, 'Raw_from_worldbank_PA.NUS.FCRF'!$C$1:$BR$1, LOOKUP(2,1/(_xlpm.r<>""),_xlpm.yrs) )} -> 2024
A8: Argentina | B8: ARG | C8: {=ROUND(_xlfn.LET( _xlpm.r, INDEX('Raw_from_worldbank_PA.NUS.FCRF'!$C$2:$BR$272, MATCH(B8,'Raw_from_worldbank_PA.NUS.FCRF'!$B$2:$B$272,0),0), LOOKUP(2,1/(_xlpm.r<>""),_xlpm.r) ),2)} -> 914.69 | D8: {=_xlfn.LET( _xlpm.r, INDEX('Raw_from_worldbank_PA.NUS.FCRF'!$C$2:$BR$272, MATCH(B8,'Raw_from_worldbank_PA.NUS.FCRF'!$B$2:$B$272,0),0), _xlpm.yrs, 'Raw_from_worldbank_PA.NUS.FCRF'!$C$1:$BR$1, LOOKUP(2,1/(_xlpm.r<>""),_xlpm.yrs) )} -> 2024
A9: Armenia | B9: ARM | C9: {=ROUND(_xlfn.LET( _xlpm.r, INDEX('Raw_from_worldbank_PA.NUS.FCRF'!$C$2:$BR$272, MATCH(B9,'Raw_from_worldbank_PA.NUS.FCRF'!$B$2:$B$272,0),0), LOOKUP(2,1/(_xlpm.r<>""),_xlpm.r) ),2)} -> 392.73 | D9: {=_xlfn.LET( _xlpm.r, INDEX('Raw_from_worldbank_PA.NUS.FCRF'!$C$2:$BR$272, MATCH(B9,'Raw_from_worldbank_PA.NUS.FCRF'!$B$2:$B$272,0),0), _xlpm.yrs, 'Raw_from_worldbank_PA.NUS.FCRF'!$C$1:$BR$1, LOOKUP(2,1/(_xlpm.r<>""),_xlpm.yrs) )} -> 2024
A10: American Samoa | B10: ASM | C10: {=ROUND(_xlfn.LET( _xlpm.r, INDEX('Raw_from_worldbank_PA.NUS.FCRF'!$C$2:$BR$272, MATCH(B10,'Raw_from_worldbank_PA.NUS.FCRF'!$B$2:$B$272,0),0), LOOKUP(2,1/(_xlpm.r<>""),_xlpm.r) ),2)} -> 1 | D10: {=_xlfn.LET( _xlpm.r, INDEX('Raw_from_worldbank_PA.NUS.FCRF'!$C$2:$BR$272, MATCH(B10,'Raw_from_worldbank_PA.NUS.FCRF'!$B$2:$B$272,0),0), _xlpm.yrs, 'Raw_from_worldbank_PA.NUS.FCRF'!$C$1:$BR$1, LOOKUP(2,1/(_xlpm.r<>""),_xlpm.yrs) )} -> 2024
A11: Antigua and Barbuda | B11: ATG | C11: {=ROUND(_xlfn.LET( _xlpm.r, INDEX('Raw_from_worldbank_PA.NUS.FCRF'!$C$2:$BR$272, MATCH(B11,'Raw_from_worldbank_PA.NUS.FCRF'!$B$2:$B$272,0),0), LOOKUP(2,1/(_xlpm.r<>""),_xlpm.r) ),2)} -> 2.7 | D11: {=_xlfn.LET( _xlpm.r, INDEX('Raw_from_worldbank_PA.NUS.FCRF'!$C$2:$BR$272, MATCH(B11,'Raw_from_worldbank_PA.NUS.FCRF'!$B$2:$B$272,0),0), _xlpm.yrs, 'Raw_from_worldbank_PA.NUS.FCRF'!$C$1:$BR$1, LOOKUP(2,1/(_xlpm.r<>""),_xlpm.yrs) )} -> 2024
A12: Australia | B12: AUS | C12: {=ROUND(_xlfn.LET( _xlpm.r, INDEX('Raw_from_worldbank_PA.NUS.FCRF'!$C$2:$BR$272, MATCH(B12,'Raw_from_worldbank_PA.NUS.FCRF'!$B$2:$B$272,0),0), LOOKUP(2,1/(_xlpm.r<>""),_xlpm.r) ),2)} -> 1.52 | D12: {=_xlfn.LET( _xlpm.r, INDEX('Raw_from_worldbank_PA.NUS.FCRF'!$C$2:$BR$272, MATCH(B12,'Raw_from_worldbank_PA.NUS.FCRF'!$B$2:$B$272,0),0), _xlpm.yrs, 'Raw_from_worldbank_PA.NUS.FCRF'!$C$1:$BR$1, LOOKUP(2,1/(_xlpm.r<>""),_xlpm.yrs) )} -> 2024
A13: Austria | B13: AUT | C13: {=ROUND(_xlfn.LET( _xlpm.r, INDEX('Raw_from_worldbank_PA.NUS.FCRF'!$C$2:$BR$272, MATCH(B13,'Raw_from_worldbank_PA.NUS.FCRF'!$B$2:$B$272,0),0), LOOKUP(2,1/(_xlpm.r<>""),_xlpm.r) ),2)} -> 0.92 | D13: {=_xlfn.LET( _xlpm.r, INDEX('Raw_from_worldbank_PA.NUS.FCRF'!$C$2:$BR$272, MATCH(B13,'Raw_from_worldbank_PA.NUS.FCRF'!$B$2:$B$272,0),0), _xlpm.yrs, 'Raw_from_worldbank_PA.NUS.FCRF'!$C$1:$BR$1, LOOKUP(2,1/(_xlpm.r<>""),_xlpm.yrs) )} -> 2024
... A216: Zimbabwe | B216: ZWE | C216: {=ROUND(_xlfn.LET( _xlpm.r, INDEX('Raw_from_worldbank_PA.NUS.FCRF'!$C$2:$BR$272, MATCH(B216,'Raw_from_worldbank_PA.NUS.FCRF'!$B$2:$B$272,0),0), LOOKUP(2,1/(_xlpm.r<>""),_xlpm.r) ),2)} -> 3266.33 | D216: {=_xlfn.LET( _xlpm.r, INDEX('Raw_from_worldbank_PA.NUS.FCRF'!$C$2:$BR$272, MATCH(B216,'Raw_from_worldbank_PA.NUS.FCRF'!$B$2:$B$272,0),0), _xlpm.yrs, 'Raw_from_worldbank_PA.NUS.FCRF'!$C$1:$BR$1, LOOKUP(2,1/(_xlpm.r<>""),_xlpm.yrs) )} -> 2024

Sheet Raw_from_worldbank_PA.NUS.FCRF
A1: Country Name | B1: Country Code | C1: Indicator Name | D1: Indicator Code | E1: 1960 | F1: 1961 | G1: 1962 | H1: 1963 | I1: 1964 | J1: 1965 | K1: 1966 | L1: 1967 | M1: 1968 | N1: 1969 | O1: 1970 | P1: 1971 | Q1: 1972 | R1: 1973 | S1: 1974 | T1: 1975 | U1: 1976 | V1: 1977 | W1: 1978 | X1: 1979 | Y1: 1980 | Z1: 1981 | AA1: 1982 | AB1: 1983 | AC1: 1984 | AD1: 1985 | AE1: 1986 | AF1: 1987 | AG1: 1988 | AH1: 1989 | AI1: 1990 | AJ1: 1991 | AK1: 1992 | AL1: 1993 | AM1: 1994 | AN1: 1995 | AO1: 1996 | AP1: 1997 | AQ1: 1998 | AR1: 1999 | AS1: 2000 | AT1: 2001 | AU1: 2002 | AV1: 2003 | AW1: 2004 | AX1: 2005 | AY1: 2006 | AZ1: 2007 | BA1: 2008 | BB1: 2009 | BC1: 2010 | BD1: 2011 | BE1: 2012 | BF1: 2013 | BG1: 2014 | BH1: 2015 | BI1: 2016 | BJ1: 2017 | BK1: 2018 | BL1: 2019 | BM1: 2020 | BN1: 2021 | BO1: 2022 | BP1: 2023 | BQ1: 2024 | BR1: 2025
A2: Aruba | B2: ABW | C2: Official exchange rate (LCU per US$, period average) | D2: PA.NUS.FCRF | AE2: 1.79 | AF2: 1.79 | AG2: 1.79 | AH2: 1.79 | AI2: 1.79 | AJ2: 1.79 | AK2: 1.79 | AL2: 1.79 | AM2: 1.79 | AN2: 1.79 | AO2: 1.79 | AP2: 1.79 | AQ2: 1.79 | AR2: 1.79 | AS2: 1.79 | AT2: 1.79 | AU2: 1.79 | AV2: 1.79 | AW2: 1.79 | AX2: 1.79 | AY2: 1.79 | AZ2: 1.79 | BA2: 1.79 | BB2: 1.79 | BC2: 1.79 | BD2: 1.79 | BE2: 1.79 | BF2: 1.79 | BG2: 1.79 | BH2: 1.79 | BI2: 1.79 | BJ2: 1.79 | BK2: 1.79 | BL2: 1.79 | BM2: 1.79 | BN2: 1.79 | BO2: 1.79 | BP2: 1.79 | BQ2: 1.79
A3: Africa Eastern and Southern | B3: AFE | C3: Official exchange rate (LCU per US$, period average) | D3: PA.NUS.FCRF
A4: Afghanistan | B4: AFG | C4: Official exchange rate (LCU per US$, period average) | D4: PA.NUS.FCRF | E4: 17.196561 | F4: 17.196561 | G4: 17.196561 | H4: 35.109645 | I4: 38.692262 | J4: 38.692262 | K4: 38.692262 | L4: 38.692262 | M4: 38.692262 | N4: 38.692262 | O4: 38.692262 | P4: 38.692262 | Q4: 38.692262 | R4: 38.692262 | S4: 38.378709 | T4: 34.929631 | U4: 34.929631 | V4: 34.929631 | W4: 34.929631 | X4: 33.846164 | Y4: 34.369458 | Z4: 38.561659 | AA4: 39.276429 | AB4: 39.276429 | AC4: 39.276429 | AD4: 39.276429 | AE4: 39.276429 | AF4: 39.276429 | AG4: 39.276429 | AH4: 39.276429 | AI4: 39.276429 | AJ4: 39.276429 | AK4: 39.276429 | AL4: 39.276429 | AM4: 38.818463 | AN4: 36.567145 | AO4: 47.5 | AP4: 47.5 | AQ4: 47.5 | AR4: 46.619531 | AS4: 47.357575 | AT4: 47.500015 | AU4: 47.263 | AV4: 48.762754 | AW4: 47.845312 | AX4: 49.494597 | AY4: 49.925331 | AZ4: 49.962018 | BA4: 50.249615 | BB4: 50.325 | BC4: 46.452461 | BD4: 46.747008 | BE4: 50.9214 | BF4: 55.3775 | BG4: 57.2475 | BH4: 61.143462 | BI4: 67.866086 | BJ4: 68.026904 | BK4: 72.083247 | BL4: 77.737949 | BM4: 76.813536
A5: Africa Western and Central | B5: AFW | C5: Official exchange rate (LCU per US$, period average) | D5: PA.NUS.FCRF
A6: Angola | B6: AGO | C6: Official exchange rate (LCU per US$, period average) | D6: PA.NUS.FCRF | E6: 2.8668443e-08 | F6: 2.873486e-08 | G6: 2.8678443e-08 | H6: 2.8752027e-08 | I6: 2.8819777e-08 | J6: 2.8778527e-08 | K6: 2.882386e-08 | L6: 2.884161e-08 | M6: 2.872761e-08 | N6: 2.8561193e-08 | O6: 2.862511e-08 | P6: 2.819112e-08 | Q6: 2.7052815e-08 | R6: 2.451462e-08 | S6: 2.5407601e-08 | T6: 2.5552181e-08 | U6: 2.9383623e-08 | V6: 2.9918e-08 | W6: 2.9918e-08 | X6: 2.9918e-08 | Y6: 2.9918e-08 | Z6: 2.9918e-08 | AA6: 2.9918e-08 | AB6: 2.9918e-08 | AC6: 2.9918e-08 | AD6: 2.9918e-08 | AE6: 2.9918e-08 | AF6: 2.9918e-08 | AG6: 2.9918e-08 | AH6: 2.9918e-08 | AI6: 2.9918e-08 | AJ6: 5.5098333e-08 | AK6: 2.5141667e-07 | AL6: 2.6601667e-06 | AM6: 5.9515e-05 | AN6: 0.0027502296 | AO6: 0.12802917 | AP6: 0.22904008 | AQ6: 0.39282352 | AR6: 2.7907062 | AS6: 10.040544 | AT6: 22.057862 | AU6: 43.530207 | AV6: 74.606301 | AW6: 83.541363 | AX6: 87.159142 | AY6: 80.368072 | AZ6: 76.706143 | BA6: 75.033354 | BB6: 79.328167 | BC6: 91.90572 | BD6: 93.93475 | BE6: 95.467955 | BF6: 96.518279 | BG6: 98.302417 | BH6: 120.0607 | BI6: 163.65643 | BJ6: 165.91595 | BK6: 252.85575 | BL6: 364.8258 | BM6: 578.25878 | BN6: 631.44196 | BO6: 460.56751 | BP6: 685.02024 | BQ6: 869.84619
A7: Albania | B7: ALB | C7: Official exchange rate (LCU per US$, period average) | D7: PA.NUS.FCRF | AK7: 75.0325 | AL7: 102.0625 | AM7: 94.623333 | AN7: 92.6975 | AO7: 104.49892 | AP7: 148.93292 | AQ7: 150.63333 | AR7: 137.69058 | AS7: 143.70942 | AT7: 143.48483 | AU7: 140.15452 | AV7: 121.86325 | AW7: 102.78005 | AX7: 99.870254 | AY7: 98.103377 | AZ7: 90.427894 | BA7: 83.894604 | BB7: 94.97812 | BC7: 103.93667 | BD7: 100.89583 | BE7: 108.18417 | BF7: 105.66917 | BG7: 105.48 | BH7: 125.96167 | BI7: 124.1425 | BJ7: 119.1 | BK7: 107.98917 | BL7: 109.85083 | BM7: 108.65 | BN7: 103.52 | BO7: 113.04167 | BP7: 100.645 | BQ7: 93.123333
A8: Andorra | B8: AND | C8: Official exchange rate (LCU per US$, period average) | D8: PA.NUS.FCRF | BN8: 0.84537656 | BO8: 0.95091553 | BP8: 0.92470962 | BQ8: 0.92436745
A9: Arab World | B9: ARB | C9: Official exchange rate (LCU per US$, period average) | D9: PA.NUS.FCRF
A10: United Arab Emirates | B10: ARE | C10: Official exchange rate (LCU per US$, period average) | D10: PA.NUS.FCRF | K10: 4.7619 | L10: 4.7619 | M10: 4.7619 | N10: 4.7619 | O10: 4.7619 | P10: 4.7479629 | Q10: 4.3859778 | R10: 3.9962713 | S10: 3.9590452 | T10: 3.961285 | U10: 3.9530725 | V10: 3.9032475 | W10: 3.8712108 | X10: 3.8156758 | Y10: 3.707365 | Z10: 3.671 | AA10: 3.671 | AB10: 3.671 | AC10: 3.671 | AD10: 3.671 | AE10: 3.671 | AF10: 3.671 | AG10: 3.671 | AH10: 3.671 | AI10: 3.671 | AJ10: 3.671 | AK10: 3.671 | AL10: 3.671 | AM10: 3.671 | AN10: 3.671 | AO10: 3.671 | AP10: 3.671125 | AQ10: 3.6725 | AR10: 3.6725 | AS10: 3.6725 | AT10: 3.6725 | AU10: 3.6725 | AV10: 3.6725 | AW10: 3.6725 | AX10: 3.6725 | AY10: 3.6725 | AZ10: 3.6725 | BA10: 3.6725 | BB10: 3.6725 | BC10: 3.6725 | BD10: 3.6725 | BE10: 3.6725 | BF10: 3.6725 | BG10: 3.6725 | BH10: 3.6725 | BI10: 3.6725 | BJ10: 3.6725 | BK10: 3.6725 | BL10: 3.6725 | BM10: 3.6725 | BN10: 3.6725 | BO10: 3.6725 | BP10: 3.6725 | BQ10: 3.6725
A11: Argentina | B11: ARG | C11: Official exchange rate (LCU per US$, period average) | D11: PA.NUS.FCRF | H11: 1.3871667e-11 | I11: 1.4039167e-11 | J11: 1.6956667e-11 | K11: 2.0915e-11 | L11: 3.33425e-11 | M11: 3.5e-11 | N11: 3.5e-11 | O11: 3.7916667e-11 | P11: 4.5216667e-11 | Q11: 5e-11 | R11: 5e-11 | S11: 5e-11 | T11: 3.6575e-10 | U11: 1.3998333e-09 | V11: 4.0763333e-09 | W11: 7.9575e-09 | X11: 1.3169667e-08 | Y11: 1.8371583e-08 | Z11: 4.4026917e-08 | AA11: 2.5922533e-07 | AB11: 1.0529957e-06 | AC11: 6.7649117e-06 | AD11: 6.01809e-05 | AE11: 9.4303167e-05 | AF11: 0.00021442983 | AG11: 0.00087526042 | AH11: 0.042333961 | AI11: 0.48758908 | AJ11: 0.95355442 | AK11: 0.99064167 | AL11: 0.99894583 | AM11: 0.99900833 | AN11: 0.99975 | AO11: 0.9996625 | AP11: 0.9995 | AQ11: 0.9995 | AR11: 0.9995 | AS11: 0.9995 | AT11: 0.9995 | AU11: 3.0632567 | AV11: 2.9006292 | AW11: 2.9233008 | AX11: 2.9036575 | AY11: 3.0543133 | AZ11: 3.0956488 | BA11: 3.1441646 | BB11: 3.7101068 | BC11: 3.8962952 | BD11: 4.1101396 | BE11: 4.5369344 | BF11: 5.4593527 | BG11: 8.075276 | BH11: 9.2331855 | BI11: 14.758175 | BJ11: 16.562707 | BK11: 28.094992 | BL11: 48.147892 | BM11: 70.539167 | BN11: 94.990742 | BO11: 130.61655 | BP11: 296.25804 | BQ11: 914.69488
A12: Armenia | B12: ARM | C12: Official exchange rate (LCU per US$, period average) | D12: PA.NUS.FCRF | AL12: 9.105 | AM12: 288.65083 | AN12: 405.90833 | AO12: 414.0415 | AP12: 490.84679 | AQ12: 504.915 | AR12: 535.06183 | AS12: 539.52583 | AT12: 555.07826 | AU12: 573.35333 | AV12: 578.76295 | AW12: 533.45083 | AX12: 457.68694 | AY12: 416.04037 | AZ12: 342.07912 | BA12: 305.9694 | BB12: 363.28329 | BC12: 373.66047 | BD12: 372.50088 | BE12: 401.76398 | BF12: 409.62575 | BG12: 415.91979 | BH12: 477.91831 | BI12: 480.48815 | BJ12: 482.71639 | BK12: 482.98795 | BL12: 480.44513 | BM12: 489.00886 | BN12: 503.76967 | BO12: 435.66618 | BP12: 392.4763 | BQ12: 392.72955
A13: American Samoa | B13: ASM | C13: Official exchange rate (LCU per US$, period average) | D13: PA.NUS.FCRF | E13: 1 | F13: 1 | G13: 1 | H13: 1 | I13: 1 | J13: 1 | K13: 1 | L13: 1 | M13: 1 | N13: 1 | O13: 1 | P13: 1 | Q13: 1 | R13: 1 | S13: 1 | T13: 1 | U13: 1 | V13: 1 | W13: 1 | X13: 1 | Y13: 1 | Z13: 1 | AA13: 1 | AB13: 1 | AC13: 1 | AD13: 1 | AE13: 1 | AF13: 1 | AG13: 1 | AH13: 1 | AI13: 1 | AJ13: 1 | AK13: 1 | AL13: 1 | AM13: 1 | AN13: 1 | AO13: 1 | AP13: 1 | AQ13: 1 | AR13: 1 | AS13: 1 | AT13: 1 | AU13: 1 | AV13: 1 | AW13: 1 | AX13: 1 | AY13: 1 | AZ13: 1 | BA13: 1 | BB13: 1 | BC13: 1 | BD13: 1 | BE13: 1 | BF13: 1 | BG13: 1 | BH13: 1 | BI13: 1 | BJ13: 1 | BK13: 1 | BL13: 1 | BM13: 1 | BN13: 1 | BO13: 1 | BP13: 1 | BQ13: 1
A14: Antigua and Barbuda | B14: ATG | C14: Official exchange rate (LCU per US$, period average) | D14: PA.NUS.FCRF | E14: 1.71429 | F14: 1.71429 | G14: 1.71429 | H14: 1.71429 | I14: 1.71429 | J14: 1.71429 | K14: 1.71429 | L14: 1.7619083 | M14: 2 | N14: 2 | O14: 2 | P14: 1.9748727 | Q14: 1.9212781 | R14: 1.9592192 | S14: 2.0532324 | T14: 2.1697958 | U14: 2.6146708 | V14: 2.7 | W14: 2.7 | X14: 2.7 | Y14: 2.7 | Z14: 2.7 | AA14: 2.7 | AB14: 2.7 | AC14: 2.7 | AD14: 2.7 | AE14: 2.7 | AF14: 2.7 | AG14: 2.7 | AH14: 2.7 | AI14: 2.7 | AJ14: 2.7 | AK14: 2.7 | AL14: 2.7 | AM14: 2.7 | AN14: 2.7 | AO14: 2.7 | AP14: 2.7 | AQ14: 2.7 | AR14: 2.7 | AS14: 2.7 | AT14: 2.7 | AU14: 2.7 | AV14: 2.7 | AW14: 2.7 | AX14: 2.7 | AY14: 2.7 | AZ14: 2.7 | BA14: 2.7 | BB14: 2.7 | BC14: 2.7 | BD14: 2.7 | BE14: 2.7 | BF14: 2.7 | BG14: 2.7 | BH14: 2.7 | BI14: 2.7 | BJ14: 2.7 | BK14: 2.7 | BL14: 2.7 | BM14: 2.7 | BN14: 2.7 | BO14: 2.7 | BP14: 2.7 | BQ14: 2.7
A15: Australia | B15: AUS | C15: Official exchange rate (LCU per US$, period average) | D15: PA.NUS.FCRF | E15: 0.892857 | F15: 0.892857 | G15: 0.892857 | H15: 0.892857 | I15: 0.892857 | J15: 0.892857 | K15: 0.892857 | L15: 0.892857 | M15: 0.892857 | N15: 0.892857 | O15: 0.892857 | P15: 0.88267026 | Q15: 0.83869781 | R15: 0.70411391 | S15: 0.69666587 | T15: 0.76387125 | U15: 0.81828408 | V15: 0.901825 | W15: 0.87365925 | X15: 0.89464092 | Y15: 0.87824433 | Z15: 0.87021458 | AA15: 0.98586283 | AB15: 1.110015 | AC15: 1.1395192 | AD15: 1.431895 | AE15: 1.4959742 | AF15: 1.42818 | AG15: 1.2799083 | AH15: 1.2645967 | AI15: 1.2810567 | AJ15: 1.2837558 | AK15: 1.3616483 | AL15: 1.47056 | AM15: 1.3677508 | AN15: 1.3490325 | AO15: 1.2778633 | AP15: 1.34738 | AQ15: 1.5918283 | AR15: 1.54995 | AS15: 1.7248267 | AT15: 1.9334425 | AU15: 1.8405625 | AV15: 1.5419142 | AW15: 1.3597525 | AX15: 1.3094733 | AY15: 1.3279734 | AZ15: 1.1950725 | BA15: 1.1921783 | BB15: 1.2821888 | BC15: 1.0901595 | BD15: 0.9694632 | BE15: 0.96580103 | BF15: 1.0358431 | BG15: 1.1093633 | BH15: 1.3310903 | BI15: 1.345214 | BJ15: 1.3047581 | BK15: 1.3384121 | BL15: 1.4385065 | BM15: 1.4530851 | BN15: 1.3312243 | BO15: 1.4416645 | BP15: 1.5051911 | BQ15: 1.515358
A16: Austria | B16: AUT | C16: Official exchange rate (LCU per US$, period average) | D16: PA.NUS.FCRF | E16: 26 | F16: 26 | G16: 26 | H16: 26 | I16: 26 | J16: 26 | K16: 26 | L16: 26 | M16: 26 | N16: 26 | O16: 26 | P16: 24.985584 | Q16: 23.115333 | R16: 19.58 | S16: 18.6925 | T16: 17.41675 | U16: 17.939667 | V16: 16.526917 | W16: 14.521667 | X16: 13.3675 | Y16: 12.938 | Z16: 15.926833 | AA16: 17.05925 | AB16: 17.963333 | AC16: 20.009083 | AD16: 20.6895 | AE16: 15.267133 | AF16: 12.6425 | AG16: 12.347667 | AH16: 13.230667 | AI16: 11.369833 | AJ16: 11.675917 | AK16: 10.989333 | AL16: 11.632183 | AM16: 11.421825 | AN16: 10.081496 | AO16: 10.586557 | AP16: 12.204244 | AQ16: 12.379065 | AR16: 0.93828307 | AS16: 1.0827051 | AT16: 1.1165331 | AU16: 1.057559 | AV16: 0.88404793 | AW16: 0.80392165 | AX16: 0.80380019 | AY16: 0.79643273 | AZ16: 0.7296724 | BA16: 0.67992268 | BB16: 0.7169577 | BC16: 0.75430899 | BD16: 0.7184139 | BE16: 0.77833812 | BF16: 0.75294512 | BG16: 0.7527282 | BH16: 0.90129642 | BI16: 0.90342144 | BJ16: 0.88520551 | BK16: 0.84677267 | BL16: 0.89327626 | BM16: 0.8755064 | BN16: 0.84549414 | BO16: 0.94962375 | BP16: 0.92483956 | BQ16: 0.92388955
A17: Azerbaijan | B17: AZE | C17: Official exchange rate (LCU per US$, period average) | D17: PA.NUS.FCRF | AK17: 0.01084 | AL17: 0.019995 | AM17: 0.314045 | AN17: 0.8827085 | AO17: 0.86025283 | AP17: 0.797075 | AQ17: 0.77379969 | AR17: 0.82403333 | AS17: 0.89483075 | AT17: 0.93131667 | AU17: 0.97216417 | AV17: 0.982146 | AW17: 0.9826955 | AX17: 0.945421 | AY17: 0.893445 | AZ17: 0.85812381 | BA17: 0.82161958 | BB17: 0.80378333 | BC17: 0.80265 | BD17: 0.78968639 | BE17: 0.78564535 | BF17: 0.78454108 | BG17: 0.7843475 | BH17: 1.0245638 | BI17: 1.5957216 | BJ17: 1.7211548 | BK17: 1.7000167 | BL17: 1.7 | BM17: 1.7 | BN17: 1.7 | BO17: 1.7 | BP17: 1.7 | BQ17: 1.7
A18: Burundi | B18: BDI | C18: Official exchange rate (LCU per US$, period average) | D18: PA.NUS.FCRF | E18: 50 | F18: 50 | G18: 50 | H18: 50 | I18: 50 | J18: 84.375 | K18: 87.5 | L18: 87.5 | M18: 87.5 | N18: 87.5 | O18: 87.5 | P18: 87.5 | Q18: 87.5 | R18: 80.026083 | S18: 78.75 | T18: 78.75 | U18: 86.25 | V18: 90 | W18: 90 | X18: 90 | Y18: 90 | Z18: 90 | AA18: 90 | AB18: 92.948333 | AC18: 119.70917 | AD18: 120.69075 | AE18: 114.17108 | AF18: 123.56383 | AG18: 140.395 | AH18: 158.66667 | AI18: 171.25542 | AJ18: 181.51258 | AK18: 208.30267 | AL18: 242.78 | AM18: 252.6625 | AN18: 249.7575 | AO18: 302.74667 | AP18: 352.35083 | AQ18: 447.76583 | AR18: 563.5625 | AS18: 720.67333 | AT18: 830.35333 | AU18: 930.74917 | AV18: 1082.62 | AW18: 1100.9 | AX18: 1081.5772 | AY18: 1028.6836 | AZ18: 1081.8697 | BA18: 1185.6908 | BB18: 1230.1792 | BC18: 1230.7483 | BD18: 1261.0733 | BE18: 1442.5056 | BF18: 1555.0908 | BG18: 1546.6867 | BH18: 1571.8983 | BI18: 1654.6267 | BJ18: 1729.055 | BK18: 1782.8769 | BL18: 1845.6229 | BM18: 1915.0462 | BN18: 1975.9509 | BO18: 2034.3066 | BP18: 2574.0517 | BQ18: 2885.2455
A19: Belgium | B19: BEL | C19: Official exchange rate (LCU per US$, period average) | D19: PA.NUS.FCRF | E19: 50 | F19: 50 | G19: 50 | H19: 50 | I19: 50 | J19: 50 | K19: 50 | L19: 50 | M19: 50 | N19: 50 | O19: 50 | P19: 49.056977 | Q19: 44.014583 | R19: 38.9765 | S19: 38.9515 | T19: 36.778917 | U19: 38.605167 | V19: 35.84275 | W19: 31.492083 | X19: 29.318667 | Y19: 29.241667 | Z19: 37.12925 | AA19: 45.690583 | AB19: 51.131667 | AC19: 57.783917 | AD19: 59.378 | AE19: 44.671917 | AF19: 37.334083 | AG19: 36.768333 | AH19: 39.404 | AI19: 33.417917 | AJ19: 34.14825 | AK19: 32.1495 | AL19: 34.596521 | AM19: 33.456497 | AN19: 29.480017 | AO19: 30.961513 | AP19: 35.773891 | AQ19: 36.298641 | AR19: 0.93828307 | AS19: 1.0827051 | AT19: 1.1165331 | AU19: 1.057559 | AV19: 0.88404793 | AW19: 0.80392165 | AX19: 0.80380019 | AY19: 0.79643273 | AZ19: 0.7296724 | BA19: 0.67992268 | BB19: 0.7169577 | BC19: 0.75430899 | BD19: 0.7184139 | BE19: 0.77833812 | BF19: 0.75294512 | BG19: 0.7527282 | BH19: 0.90129642 | BI19: 0.90342144 | BJ19: 0.88520551 | BK19: 0.84677267 | BL19: 0.89327626 | BM19: 0.8755064 | BN19: 0.84549414 | BO19: 0.94962375 | BP19: 0.92483956 | BQ19: 0.92388955
A20: Benin | B20: BEN | C20: Official exchange rate (LCU per US$, period average) | D20: PA.NUS.FCRF | E20: 245.1951 | F20: 245.2601 | G20: 245.01385 | H20: 245.01635 | I20: 245.02718 | J20: 245.06093 | K20: 245.67844 | L20: 246.00094 | M20: 247.56469 | N20: 259.96057 | O20: 276.40314 | P20: 275.35646 | Q20: 252.02763 | R20: 222.88918 | S20: 240.70467 | T20: 214.3129 | U20: 238.95049 | V20: 245.67969 | W20: 225.65586 | X20: 212.72164 | Y20: 211.27956 | Z20: 271.73145 | AA20: 328.60625 | AB20: 381.06604 | AC20: 436.95667 | AD20: 449.26296 | AE20: 346.3059 | AF20: 300.53656 | AG20: 297.84822 | AH20: 319.0083 | AI20: 272.26479 | AJ20: 282.10691 | AK20: 264.6918 | AL20: 283.16258 | AM20: 555.2047 | AN20: 499.14843 | AO20: 511.55243 | AP20: 583.66937 | AQ20: 589.95177 | AR20: 615.47335 | AS20: 710.20798 | AT20: 732.39769 | AU20: 693.71323 | AV20: 579.89743 | AW20: 527.33803 | AX20: 527.25836 | AY20: 522.42562 | AZ20: 478.63372 | BA20: 446.00004 | BB20: 470.29342 | BC20: 494.79426 | BD20: 471.24863 | BE20: 510.55634 | BF20: 493.89962 | BG20: 493.75733 | BH20: 591.2117 | BI20: 592.60562 | BJ20: 580.65675 | BK20: 555.44646 | BL20: 585.95081 | BM20: 574.29455 | BN20: 554.6078 | BO20: 622.91235 | BP20: 606.65498 | BQ20: 606.3453
A21: Burkina Faso | B21: BFA | C21: Official exchange rate (LCU per US$, period average) | D21: PA.NUS.FCRF | E21: 245.1951 | F21: 245.2601 | G21: 245.01385 | H21: 245.01635 | I21: 245.02718 | J21: 245.06093 | K21: 245.67844 | L21: 246.00094 | M21: 247.56469 | N21: 259.96057 | O21: 276.40314 | P21: 275.35646 | Q21: 252.02763 | R21: 222.88918 | S21: 240.70467 | T21: 214.3129 | U21: 238.95049 | V21: 245.67969 | W21: 225.65586 | X21: 212.72164 | Y21: 211.27956 | Z21: 271.73145 | AA21: 328.60625 | AB21: 381.06604 | AC21: 436.95667 | AD21: 449.26296 | AE21: 346.3059 | AF21: 300.53656 | AG21: 297.84822 | AH21: 319.0083 | AI21: 272.26479 | AJ21: 282.10691 | AK21: 264.6918 | AL21: 283.16258 | AM21: 555.2047 | AN21: 499.14843 | AO21: 511.55243 | AP21: 583.66937 | AQ21: 589.95177 | AR21: 615.47335 | AS21: 710.20798 | AT21: 732.39769 | AU21: 693.71323 | AV21: 579.89743 | AW21: 527.33803 | AX21: 527.25836 | AY21: 522.42562 | AZ21: 478.63372 | BA21: 446.00004 | BB21: 470.29342 | BC21: 494.79426 | BD21: 471.24863 | BE21: 510.55634 | BF21: 493.89962 | BG21: 493.75733 | BH21: 591.2117 | BI21: 592.60562 | BJ21: 580.65675 | BK21: 555.44646 | BL21: 585.91101 | BM21: 575.586 | BN21: 554.53068 | BO21: 623.7597 | BP21: 606.56975 | BQ21: 606.3453
A22: Bangladesh | B22: BGD | C22: Official exchange rate (LCU per US$, period average) | D22: PA.NUS.FCRF | P22: 7.8688426 | Q22: 7.7001842 | R22: 7.849816 | S22: 8.2260022 | T22: 12.18618 | U22: 15.399169 | V22: 15.3751 | W22: 15.016117 | X22: 15.551925 | Y22: 15.454058 | Z22: 17.986692 | AA22: 22.117883 | AB22: 24.615425 | AC22: 25.353933 | AD22: 27.994592 | AE22: 30.4069 | AF22: 30.949833 | AG22: 31.733249 | AH22: 32.27 | AI22: 34.568808 | AJ22: 36.596183 | AK22: 38.950758 | AL22: 39.567257 | AM22: 40.211739 | AN22: 40.278318 | AO22: 41.794168 | AP22: 43.892116 | AQ22: 46.905652 | AR22: 49.0854 | AS22: 52.141667 | AT22: 55.806667 | AU22: 57.888 | AV22: 58.15004 | AW22: 59.512658 | AX22: 64.327475 | AY22: 68.933233 | AZ22: 68.874875 | BA22: 68.598275 | BB22: 69.039067 | BC22: 69.649292 | BD22: 74.1524 | BE22: 81.862658 | BF22: 78.103235 | BG22: 77.641408 | BH22: 77.946908 | BI22: 78.468092 | BJ22: 80.437542 | BK22: 83.466202 | BL22: 84.453523 | BM22: 84.871392 | BN22: 85.083763 | BO22: 91.745454 | BP22: 106.30948 | BQ22: 115.60365
A23: Bulgaria | B23: BGR | C23: Official exchange rate (LCU per US$, period average) | D23: PA.NUS.FCRF | E23: 0.00117 | F23: 0.00117 | G23: 0.00117 | H23: 0.00117 | I23: 0.00117 | J23: 0.00117 | K23: 0.00117 | L23: 0.00117 | M23: 0.00117 | N23: 0.00117 | O23: 0.00117 | P23: 0.00117 | Q23: 0.00108 | R23: 0.00097916667 | S23: 0.00097 | AJ23: 0.01778825 | AK23: 0.023341167 | AL23: 0.027593583 | AM23: 0.054133667 | AN23: 0.067170833 | AO23: 0.17788867 | AP23: 1.6818792 | AQ23: 1.7603583 | AR23: 1.8363833 | AS23: 2.123275 | AT23: 2.1847083 | AU23: 2.076975 | AV23: 1.7327017 | AW23: 1.5751089 | AX23: 1.5741333 | AY23: 1.5592667 | AZ23: 1.42905 | BA23: 1.3371167 | BB23: 1.4066917 | BC23: 1.4773917 | BD23: 1.4064583 | BE23: 1.52205 | BF23: 1.4735667 | BG23: 1.4741833 | BH23: 1.7644 | BI23: 1.7680417 | BJ23: 1.7354583 | BK23: 1.6570417 | BL23: 1.7470417 | BM23: 1.7163333 | BN23: 1.653775 | BO23: 1.8601417 | BP23: 1.8089667 | BQ23: 1.8078417
A24: Bahrain | B24: BHR | C24: Official exchange rate (LCU per US$, period average) | D24: PA.NUS.FCRF | K24: 0.47619 | L24: 0.47619 | M24: 0.47619 | N24: 0.47619 | O24: 0.47619 | P24: 0.47479629 | Q24: 0.43859778 | R24: 0.39963031 | S24: 0.39474 | T24: 0.3955 | U24: 0.39559917 | V24: 0.39565 | W24: 0.38745333 | X24: 0.3816175 | Y24: 0.37700023 | Z24: 0.376 | AA24: 0.376 | AB24: 0.376 | AC24: 0.376 | AD24: 0.376 | AE24: 0.376 | AF24: 0.376 | AG24: 0.376 | AH24: 0.376 | AI24: 0.376 | AJ24: 0.376 | AK24: 0.376 | AL24: 0.37599999 | AM24: 0.37599996 | AN24: 0.37599997 | AO24: 0.37599997 | AP24: 0.37599996 | AQ24: 0.37599996 | AR24: 0.37599998 | AS24: 0.376 | AT24: 0.376 | AU24: 0.376 | AV24: 0.376 | AW24: 0.376 | AX24: 0.376 | AY24: 0.376 | AZ24: 0.376 | BA24: 0.376 | BB24: 0.376 | BC24: 0.376 | BD24: 0.376 | BE24: 0.376 | BF24: 0.376 | BG24: 0.376 | BH24: 0.376 | BI24: 0.376 | BJ24: 0.376 | BK24: 0.376 | BL24: 0.376 | BM24: 0.376 | BN24: 0.376 | BO24: 0.376 | BP24: 0.376 | BQ24: 0.376
A25: Bahamas, The | B25: BHS | C25: Official exchange rate (LCU per US$, period average) | D25: PA.NUS.FCRF | E25: 1.02041 | F25: 1.02041 | G25: 1.02041 | H25: 1.02041 | I25: 1.02041 | J25: 1.02041 | K25: 1 | L25: 1 | M25: 1 | N25: 1 | O25: 1 | P25: 1 | Q25: 1 | R25: 1 | S25: 1 | T25: 1 | U25: 1 | V25: 1 | W25: 1 | X25: 1 | Y25: 1 | Z25: 1 | AA25: 1 | AB25: 1 | AC25: 1 | AD25: 1 | AE25: 1 | AF25: 1 | AG25: 1 | AH25: 1 | AI25: 1 | AJ25: 1 | AK25: 1 | AL25: 1 | AM25: 1 | AN25: 1 | AO25: 1 | AP25: 1 | AQ25: 1 | AR25: 1 | AS25: 1 | AT25: 1 | AU25: 1 | AV25: 1 | AW25: 1 | AX25: 1 | AY25: 1 | AZ25: 1 | BA25: 1 | BB25: 1 | BC25: 1 | BD25: 1 | BE25: 1 | BF25: 1 | BG25: 1 | BH25: 1 | BI25: 1 | BJ25: 1 | BK25: 1 | BL25: 1 | BM25: 1 | BN25: 1 | BO25: 1 | BP25: 1 | BQ25: 1
A26: Bosnia and Herzegovina | B26: BIH | C26: Official exchange rate (LCU per US$, period average) | D26: PA.NUS.FCRF | AP26: 1.7340558 | AQ26: 1.7596676 | AR26: 1.8357954 | AS26: 2.1228595 | AT26: 2.1856596 | AU26: 2.0781704 | AV26: 1.7329322 | AW26: 1.575157 | AX26: 1.572722 | AY26: 1.559072 | AZ26: 1.4290027 | BA26: 1.3351957 | BB26: 1.4078912 | BC26: 1.4767396 | BD26: 1.4069366 | BE26: 1.52221 | BF26: 1.4730513 | BG26: 1.4741692 | BH26: 1.7634916 | BI26: 1.768139 | BJ26: 1.7353527 | BK26: 1.6569854 | BL26: 1.7470865 | BM26: 1.7169705 | BN26: 1.6536062 | BO26: 1.8593259 | BP26: 1.8092028 | BQ26: 1.8075636
A27: Belarus | B27: BLR | C27: Official exchange rate (LCU per US$, period average) | D27: PA.NUS.FCRF | AM27: 0.00036411125 | AN27: 0.0011520967 | AO27: 0.0013229877 | AP27: 0.002602055 | AQ27: 0.004612762 | AR27: 0.024929533 | AS27: 0.087675 | AT27: 0.139 | AU27: 0.17909167 | AV27: 0.20512708 | AW27: 0.21602575 | AX27: 0.215382 | AY27: 0.21445642 | AZ27: 0.21460783 | BA27: 0.21363975 | BB27: 0.27930492 | BC27: 0.297851 | BD27: 0.49746333 | BE27: 0.83368983 | BF27: 0.88800525 | BG27: 1.0224103 | BH27: 1.5925988 | BI27: 1.9895628 | BJ27: 1.9323417 | BK27: 2.0376083 | BL27: 2.0917833 | BM27: 2.439575 | BN27: 2.538675 | BO27: 2.6261 | BP27: 3.00735 | BQ27: 3.2461917
A28: Belize | B28: BLZ | C28: Official exchange rate (LCU per US$, period average) | D28: PA.NUS.FCRF | E28: 1.42857 | F28: 1.42857 | G28: 1.42857 | H28: 1.42857 | I28: 1.42857 | J28: 1.42857 | K28: 1.42857 | L28: 1.4484117 | M28: 1.66667 | N28: 1.66667 | O28: 1.66667 | P28: 1.6436821 | Q28: 1.6015618 | R28: 1.6326838 | S28: 1.7109268 | T28: 1.8080437 | U28: 2.2256731 | V28: 2 | W28: 2 | X28: 2 | Y28: 2 | Z28: 2 | AA28: 2 | AB28: 2 | AC28: 2 | AD28: 2 | AE28: 2 | AF28: 2 | AG28: 2 | AH28: 2 | AI28: 2 | AJ28: 2 | AK28: 2 | AL28: 2 | AM28: 2 | AN28: 2 | AO28: 2 | AP28: 2 | AQ28: 2 | AR28: 2 | AS28: 2 | AT28: 2 | AU28: 2 | AV28: 2 | AW28: 2 | AX28: 2 | AY28: 2 | AZ28: 2 | BA28: 2 | BB28: 2 | BC28: 2 | BD28: 2 | BE28: 2 | BF28: 2 | BG28: 2 | BH28: 2 | BI28: 2 | BJ28: 2 | BK28: 2 | BL28: 2 | BM28: 2 | BN28: 2 | BO28: 2 | BP28: 2 | BQ28: 2
A29: Bermuda | B29: BMU | C29: Official exchange rate (LCU per US$, period average) | D29: PA.NUS.FCRF | E29: 0.85714 | F29: 0.85714 | G29: 0.85714 | H29: 0.85714 | I29: 0.85714 | J29: 0.85714 | K29: 0.85714 | L29: 0.869045 | M29: 1 | N29: 1 | O29: 1 | P29: 1 | Q29: 1 | R29: 1 | S29: 1 | T29: 1 | U29: 1 | V29: 1 | W29: 1 | X29: 1 | Y29: 1 | Z29: 1 | AA29: 1 | AB29: 1 | AC29: 1 | AD29: 1 | AE29: 1 | AF29: 1 | AG29: 1 | AH29: 1 | AI29: 1 | AJ29: 1 | AK29: 1 | AL29: 1 | AM29: 1 | AN29: 1 | AO29: 1 | AP29: 1 | AQ29: 1 | AR29: 1 | AS29: 1 | AT29: 1 | AU29: 1 | AV29: 1 | AW29: 1 | AX29: 1 | AY29: 1 | AZ29: 1 | BA29: 1 | BB29: 1 | BC29: 1 | BD29: 1 | BE29: 1 | BF29: 1 | BG29: 1 | BH29: 1 | BI29: 1 | BJ29: 1 | BK29: 1 | BL29: 1 | BM29: 1 | BN29: 1 | BO29: 1 | BP29: 1 | BQ29: 1
A30: Bolivia | B30: BOL | C30: Official exchange rate (LCU per US$, period average) | D30: PA.NUS.FCRF | E30: 1.188e-05 | F30: 1.188e-05 | G30: 1.188e-05 | H30: 1.188e-05 | I30: 1.188e-05 | J30: 1.188e-05 | K30: 1.188e-05 | L30: 1.188e-05 | M30: 1.188e-05 | N30: 1.188e-05 | O30: 1.188e-05 | P30: 1.188e-05 | Q30: 1.3295e-05 | R30: 2.001e-05 | S30: 2.001e-05 | T30: 2.001e-05 | U30: 2.001e-05 | V30: 2.001e-05 | W30: 2.001e-05 | X30: 2.0403333e-05 | Y30: 2.452e-05 | Z30: 2.452e-05 | AA30: 6.4071667e-05 | AB30: 0.00023163 | AC30: 0.0031359092 | AD30: 0.44002901 | AE30: 1.9219583 | AF30: 2.05485 | AG30: 2.3502417 | AH30: 2.6916833 | AI30: 3.17265 | AJ30: 3.5806083 | AK30: 3.9005167 | AL30: 4.2650833 | AM30: 4.6205167 | AN30: 4.8003417 | AO30: 5.0746125 | AP30: 5.2542583 | AQ30: 5.5101333 | AR30: 5.8124083 | AS30: 6.1835417 | AT30: 6.6069167 | AU30: 7.17 | AV30: 7.6591667 | AW30: 7.9362667 | AX30: 8.0660625 | AY30: 8.0116167 | AZ30: 7.8512452 | BA30: 7.2383207 | BB30: 7.02 | BC30: 7.0166667 | BD30: 6.9369625 | BE30: 6.91 | BF30: 6.91 | BG30: 6.91 | BH30: 6.91 | BI30: 6.91 | BJ30: 6.91 | BK30: 6.91 | BL30: 6.91 | BM30: 6.91 | BN30: 6.91 | BO30: 6.91 | BP30: 6.91 | BQ30: 6.91
A31: Brazil | B31: BRA | C31: Official exchange rate (LCU per US$, period average) | D31: PA.NUS.FCRF | E31: 8.0997053e-14 | F31: 1.1684348e-13 | G31: 1.6776416e-13 | H31: 2.488694e-13 | I31: 5.4202392e-13 | J31: 8.2165489e-13 | K31: 9.6071305e-13 | L31: 1.1526032e-12 | M31: 1.4695953e-12 | N31: 1.7633628e-12 | O31: 1.9878538e-12 | P31: 2.2882209e-12 | Q31: 2.56796e-12 | R31: 2.6509405e-12 | S31: 2.9383611e-12 | T31: 3.5168445e-12 | U31: 4.6187073e-12 | V31: 6.1208673e-12 | W31: 7.8197498e-12 | X31: 1.1660691e-11 | Y31: 2.2812319e-11 | Z31: 4.0300109e-11 | AA31: 7.7685443e-11 | AB31: 2.4971817e-10 | AC31: 7.9974132e-10 | AD31: 2.6832423e-09 | AE31: 5.9096823e-09 | AF31: 1.6976308e-08 | AG31: 1.1354767e-07 | AH31: 1.2263874e-06 | AI31: 2.9557268e-05 | AJ31: 0.00017596144 | AK31: 0.0019530235 | AL31: 0.038276611 | AM31: 0.66468351 | AN31: 0.91766667 | AO31: 1.0051 | AP31: 1.0779917 | AQ31: 1.1605167 | AR31: 1.8139328 | AS31: 1.8294231 | AT31: 2.3496317 | AU31: 2.920363 | AV31: 3.0774751 | AW31: 2.9251194 | AX31: 2.43439 | AY31: 2.1753267 | AZ31: 1.9470583 | BA31: 1.8337667 | BB31: 1.9994282 | BC31: 1.7592267 | BD31: 1.6728288 | BE31: 1.9530686 | BF31: 2.1560892 | BG31: 2.352952 | BH31: 3.3269044 | BI31: 3.4913134 | BJ31: 3.1913894 | BK31: 3.6538254 | BL31: 3.9444711 | BM31: 5.1551788 | BN31: 5.3944008 | BO31: 5.1639703 | BP31: 4.9943798 | BQ31: 5.3889349
A32: Barbados | B32: BRB | C32: Official exchange rate (LCU per US$, period average) | D32: PA.NUS.FCRF | E32: 1.71429 | F32: 1.71429 | G32: 1.71429 | H32: 1.71429 | I32: 1.71429 | J32: 1.71429 | K32: 1.71429 | L32: 1.7380992 | M32: 2 | N32: 2 | O32: 2 | P32: 1.9748762 | Q32: 1.9212807 | R32: 1.9592205 | S32: 2.0532309 | T32: 2.0188666 | U32: 2 | V32: 2 | W32: 2 | X32: 2 | Y32: 2 | Z32: 2 | AA32: 2 | AB32: 2 | AC32: 2 | AD32: 2 | AE32: 2 | AF32: 2 | AG32: 2 | AH32: 2 | AI32: 2 | AJ32: 2 | AK32: 2 | AL32: 2 | AM32: 2 | AN32: 2 | AO32: 2 | AP32: 2 | AQ32: 2 | AR32: 2 | AS32: 2 | AT32: 2 | AU32: 2 | AV32: 2 | AW32: 2 | AX32: 2 | AY32: 2 | AZ32: 2 | BA32: 2 | BB32: 2 | BC32: 2 | BD32: 2 | BE32: 2 | BF32: 2 | BG32: 2 | BH32: 2 | BI32: 2 | BJ32: 2 | BK32: 2 | BL32: 2 | BM32: 2 | BN32: 2 | BO32: 2 | BP32: 2 | BQ32: 2
A33: Brunei Darussalam | B33: BRN | C33: Official exchange rate (LCU per US$, period average) | D33: PA.NUS.FCRF | E33: 3.06122 | F33: 3.06122 | G33: 3.06122 | H33: 3.06122 | I33: 3.06122 | J33: 3.06122 | K33: 3.06122 | L33: 3.06122 | M33: 3.06122 | N33: 3.06122 | O33: 3.06122 | P33: 3.0522604 | Q33: 2.8195559 | R33: 2.4585797 | S33: 2.4368667 | T33: 2.3713 | U33: 2.4708417 | V33: 2.4394 | W33: 2.274025 | X33: 2.1745583 | Y33: 2.1412083 | Z33: 2.1126917 | AA33: 2.140025 | AB33: 2.11305 | AC33: 2.1330833 | AD33: 2.20015 | AE33: 2.1774167 | AF33: 2.1059833 | AG33: 2.012425 | AH33: 1.9502583 | AI33: 1.8125333 | AJ33: 1.72755 | AK33: 1.6289667 | AL33: 1.6157908 | AM33: 1.5274442 | AN33: 1.417375 | AO33: 1.4100408 | AP33: 1.4848058 | AQ33: 1.6736017 | AR33: 1.6949567 | AS33: 1.7239633 | AT33: 1.7917225 | AU33: 1.7905883 | AV33: 1.7421833 | AW33: 1.6902283 | AX33: 1.6643975 | AY33: 1.5889333 | AZ33: 1.5071017 | BA33: 1.4171667 | BB33: 1.4545693 | BC33: 1.3635095 | BD33: 1.257913 | BE33: 1.249567 | BF33: 1.2511657 | BG33: 1.2670401 | BH33: 1.3749108 | BI33: 1.3813469 | BJ33: 1.3808912 | BK33: 1.3489186 | BL33: 1.3642185 | BM33: 1.3797034 | BN33: 1.343807 | BO33: 1.3789564 | BP33: 1.3430796 | BQ33: 1.3360333
A34: Bhutan | B34: BTN | C34: Official exchange rate (LCU per US$, period average) | D34: PA.NUS.FCRF | E34: 4.7619 | F34: 4.7619 | G34: 4.7619 | H34: 4.7619 | I34: 4.7619 | J34: 4.7619 | K34: 6.359125 | L34: 7.5 | M34: 7.5 | N34: 7.5 | O34: 7.5 | P34: 7.4919352 | Q34: 7.5944684 | R34: 7.7420386 | S34: 8.1016032 | T34: 8.3758919 | U34: 8.9604127 | V34: 8.7385762 | W34: 8.1928403 | X34: 8.1257909 | Y34: 7.8629447 | Z34: 8.6585228 | AA34: 9.4551319 | AB34: 10.098898 | AC34: 11.362583 | AD34: 12.36875 | AE34: 12.610833 | AF34: 12.9615 | AG34: 13.917083 | AH34: 16.2255 | AI34: 17.5035 | AJ34: 22.742433 | AK34: 25.918083 | AL34: 30.493292 | AM34: 31.373742 | AN34: 32.427077 | AO34: 35.433173 | AP34: 36.313286 | AQ34: 41.259365 | AR34: 43.055428 | AS34: 44.941605 | AT34: 47.186414 | AU34: 48.610319 | AV34: 46.583284 | AW34: 45.316467 | AX34: 44.099975 | AY34: 45.307008 | AZ34: 41.348533 | BA34: 43.505183 | BB34: 48.405267 | BC34: 45.725812 | BD34: 46.670467 | BE34: 53.437233 | BF34: 58.597845 | BG34: 61.029514 | BH34: 64.151944 | BI34: 67.195313 | BJ34: 65.121569 | BK34: 68.389467 | BL34: 70.420341 | BM34: 74.099567 | BN34: 73.918013 | BO34: 78.604491 | BP34: 82.599276 | BQ34: 83.669282
A35: Botswana | B35: BWA | C35: Official exchange rate (LCU per US$, period average) | D35: PA.NUS.FCRF | E35: 0.71332088 | F35: 0.71469444 | G35: 0.71326549 | H35: 0.71528719 | I35: 0.71725865 | J35: 0.7163344 | K35: 0.71698343 | L35: 0.71704962 | M35: 0.71699816 | N35: 0.71805713 | O35: 0.71641352 | P35: 0.71244376 | Q35: 0.77282841 | R35: 0.69411414 | S35: 0.679477 | T35: 0.7395077 | U35: 0.869565 | V35: 0.84195967 | W35: 0.828157 | X35: 0.81500667 | Y35: 0.777225 | Z35: 0.83673833 | AA35: 1.0296608 | AB35: 1.0969258 | AC35: 1.2983733 | AD35: 1.9025667 | AE35: 1.8791442 | AF35: 1.6789408 | AG35: 1.8285875 | AH35: 2.0148858 | AI35: 1.8604658 | AJ35: 2.0215567 | AK35: 2.109725 | AL35: 2.423075 | AM35: 2.6846455 | AN35: 2.7722067 | AO35: 3.3241967 | AP35: 3.6507633 | AQ35: 4.22588 | AR35: 4.6243953 | AS35: 5.1022417 | AT35: 5.8414167 | AU35: 6.3277917 | AV35: 4.9496667 | AW35: 4.6938333 | AX35: 5.11675 | AY35: 5.8303 | AZ35: 6.1394083 | BA35: 6.8268583 | BB35: 7.1551417 | BC35: 6.793625 | BD35: 6.8382333 | BE35: 7.640525 | BF35: 8.3989083 | BG35: 8.9760833 | BH35: 10.128992 | BI35: 10.901158 | BJ35: 10.347417 | BK35: 10.199975 | BL35: 10.755867 | BM35: 11.456242 | BN35: 11.087258 | BO35: 12.368808 | BP35: 13.596383 | BQ35: 13.563133
A36: Central African Republic | B36: CAF | C36: Official exchange rate (LCU per US$, period average) | D36: PA.NUS.FCRF | E36: 245.1951 | F36: 245.2601 | G36: 245.01385 | H36: 245.01635 | I36: 245.02718 | J36: 245.06093 | K36: 245.67844 | L36: 246.00094 | M36: 247.56469 | N36: 259.96057 | O36: 276.40314 | P36: 275.35646 | Q36: 252.02763 | R36: 222.88918 | S36: 240.70467 | T36: 214.3129 | U36: 238.95049 | V36: 245.67969 | W36: 225.65586 | X36: 212.72164 | Y36: 211.27956 | Z36: 271.73145 | AA36: 328.60625 | AB36: 381.06604 | AC36: 436.95667 | AD36: 449.26296 | AE36: 346.3059 | AF36: 300.53656 | AG36: 297.84822 | AH36: 319.0083 | AI36: 272.26479 | AJ36: 282.10691 | AK36: 264.6918 | AL36: 283.16258 | AM36: 555.2047 | AN36: 499.14843 | AO36: 511.55243 | AP36: 583.66937 | AQ36: 589.95177 | AR36: 615.47335 | AS36: 710.20798 | AT36: 732.39769 | AU36: 693.71323 | AV36: 579.89743 | AW36: 527.33803 | AX36: 527.25836 | AY36: 522.42562 | AZ36: 478.63372 | BA36: 446.00004 | BB36: 470.29342 | BC36: 494.79426 | BD36: 471.24863 | BE36: 510.55634 | BF36: 493.89962 | BG36: 493.75733 | BH36: 591.2117 | BI36: 592.60562 | BJ36: 580.65675 | BK36: 555.44646 | BL36: 585.91101 | BM36: 575.586 | BN36: 554.53068 | BO36: 623.7597 | BP36: 606.56975 | BQ36: 606.3453
A37: Canada | B37: CAN | C37: Official exchange rate (LCU per US$, period average) | D37: PA.NUS.FCRF | E37: 0.96976679 | F37: 1.0130625 | G37: 1.0687692 | H37: 1.0785143 | I37: 1.0785984 | J37: 1.0779843 | K37: 1.0773416 | L37: 1.0787104 | M37: 1.0774714 | N37: 1.0767805 | O37: 1.0442187 | P37: 1.0098105 | Q37: 0.99066256 | R37: 1.0000901 | S37: 0.97801753 | T37: 1.0171593 | U37: 0.9860283 | V37: 1.0634416 | W37: 1.1406592 | X37: 1.1714245 | Y37: 1.1692269 | Z37: 1.1989031 | AA37: 1.2337349 | AB37: 1.2324118 | AC37: 1.2950656 | AD37: 1.3655074 | AE37: 1.3894711 | AF37: 1.3259826 | AG37: 1.2307008 | AH37: 1.1839721 | AI37: 1.1667736 | AJ37: 1.1457258 | AK37: 1.2087229 | AL37: 1.2900879 | AM37: 1.3656734 | AN37: 1.3724454 | AO37: 1.3635216 | AP37: 1.384598 | AQ37: 1.4835053 | AR37: 1.4857048 | AS37: 1.4853941 | AT37: 1.54884 | AU37: 1.5703428 | AV37: 1.4010145 | AW37: 1.3012816 | AX37: 1.2114051 | AY37: 1.1343447 | AZ37: 1.0740456 | BA37: 1.0670869 | BB37: 1.1415354 | BC37: 1.0301127 | BD37: 0.98925816 | BE37: 0.99936474 | BF37: 1.0301374 | BG37: 1.1047471 | BH37: 1.2787862 | BI37: 1.3256152 | BJ37: 1.2979358 | BK37: 1.2958179 | BL37: 1.3267934 | BM37: 1.3411527 | BN37: 1.2538769 | BO37: 1.3015548 | BP37: 1.3499086 | BQ37: 1.3693598
A38: Central Europe and the Baltics | B38: CEB | C38: Official exchange rate (LCU per US$, period average) | D38: PA.NUS.FCRF
A39: Switzerland | B39: CHE | C39: Official exchange rate (LCU per US$, period average) | D39: PA.NUS.FCRF | E39: 4.37295 | F39: 4.37295 | G39: 4.37295 | H39: 4.37295 | I39: 4.37295 | J39: 4.37295 | K39: 4.37295 | L39: 4.37295 | M39: 4.37295 | N39: 4.37295 | O39: 4.37295 | P39: 4.1338542 | Q39: 3.81925 | R39: 3.1648333 | S39: 2.97925 | T39: 2.5812833 | U39: 2.4996417 | V39: 2.403525 | W39: 1.788025 | X39: 1.662725 | Y39: 1.6757083 | Z39: 1.9642417 | AA39: 2.030275 | AB39: 2.0991417 | AC39: 2.3496833 | AD39: 2.457125 | AE39: 1.7989167 | AF39: 1.4911917 | AG39: 1.4633 | AH39: 1.635925 | AI39: 1.3891583 | AJ39: 1.4339917 | AK39: 1.4062183 | AL39: 1.4776167 | AM39: 1.3676925 | AN39: 1.1824692 | AO39: 1.23601 | AP39: 1.4513125 | AQ39: 1.4498133 | AR39: 1.502155 | AS39: 1.6888425 | AT39: 1.687615 | AU39: 1.5586075 | AV39: 1.3466508 | AW39: 1.2434958 | AX39: 1.2451767 | AY39: 1.2538433 | AZ39: 1.2003658 | BA39: 1.08309 | BB39: 1.0881417 | BC39: 1.0429056 | BD39: 0.88804203 | BE39: 0.93768448 | BF39: 0.92690355 | BG39: 0.91615105 | BH39: 0.96238133 | BI39: 0.98539439 | BJ39: 0.98469167 | BK39: 0.97789167 | BL39: 0.99370917 | BM39: 0.938965 | BN39: 0.91384583 | BO39: 0.9548325 | BP39: 0.89849 | BQ39: 0.88044083
A40: Channel Islands | B40: CHI | C40: Official exchange rate (LCU per US$, period average) | D40: PA.NUS.FCRF | E40: 0.357143 | F40: 0.357143 | G40: 0.357143 | H40: 0.357143 | I40: 0.357143 | J40: 0.357143 | K40: 0.357143 | L40: 0.36210333 | M40: 0.416667 | N40: 0.416667 | O40: 0.416667 | P40: 0.41092024 | Q40: 0.40039046 | R40: 0.40817095 | S40: 0.42775644 | T40: 0.45204117 | U40: 0.55650983 | V40: 0.573272 | W40: 0.52150458 | X40: 0.47218117 | Y40: 0.430295 | Z40: 0.49764133 | AA40: 0.57244683 | AB40: 0.65972458 | AC40: 0.75180667 | AD40: 0.779246 | AE40: 0.68219733 | AF40: 0.6119265 | AG40: 0.56217017 | AH40: 0.61117275 | AI40: 0.56317717 | AJ40: 0.56701533 | AK40: 0.56977417 | AL40: 0.66675655 | AM40: 0.6534266 | AN40: 0.63366812 | AO40: 0.64095826 | AP40: 0.61083611 | AQ40: 0.60382359 | AR40: 0.61805685 | AS40: 0.66093083 | AT40: 0.694655 | AU40: 0.66722333 | AV40: 0.6124725 | AW40: 0.54618 | AX40: 0.54999833 | AY40: 0.54348667 | AZ40: 0.49977167 | BA40: 0.54396625 | BB40: 0.64191926 | BC40: 0.64717935 | BD40: 0.62414084 | BE40: 0.63304699 | BF40: 0.63966058 | BG40: 0.60772963 | BH40: 0.65454548 | BI40: 0.74063446 | BJ40: 0.77697668 | BK40: 0.74953154 | BL40: 0.78344511 | BM40: 0.77999958 | BN40: 0.72706494 | BO40: 0.81130172 | BP40: 0.80453891 | BQ40: 0.78241458
...

Sheet source link
A1: Official exchange rate (LCU per US$, period average) | Data
