Workbook

Sheet Instructions
B2: Instruction Sheet
B3: This workbook is developed to guide the data preparation process for GEM model. Blue sheet tabs require researcher input for documentation and simulation data preparation.
B4: * Establish a fixed period (e.g., 1 year) as recruitment period for baseline information (e.g., Disease History) and determine a follow-up period for outcomes
B5: Tab No.1 | C5: Codebook
B6: This list contains the definitions of variables in GEM model.
B7: 1) Data Input
B8: This table contains definitions of all variables in order to run simulation.
B9: Extracted information for study samples should be provided in the DataInput tab
B10: It is recommended that researchers try their best to gather information on as many variables as possible.
B11: 2) Outcomes Cohort Level
B12: This table contains definitions of outcome variables
B13: Tab No.2 | C13: Included Study Documentation
B14: This is a standard table for documenting included studies
B15: This table contains one example, which is only used to guide data preparation process.
B16: Tab No.3 | C16: DataInput
B17: This is a standard table for input data preparation
B18: Researchers should gather input data for each study cohort. Studies should have at a minimum T2D and obesity rate data. CKD, CVD, ESKD, and obesity by class (1-3) rates, and average BMI, should be included if available.
B19: This table contains an example of study data, which is only used to guide data preparation process.
B20: Tab No.4 | C20: ComparisonOutcomes
B21: This is a standard table to document study outcomes for comparison to simulated outcomes
B22: This table contains an example of study data, which is only used to guide data preparation process.
B23: Tab No.5 | C23: SimOutcomes
B24: This is a standard table for the projected outcomes
B25: The model takes information from the "DataInput" tab and generates the risk of outcomes in the "SimOutcomes" tab.
B26: This table also contains an example.

Sheet InstructionsPersonLevel
B2: Instruction Sheet
B3: This sheet is developed to guide the data preparation process for GEM model
B4: * Establish a fixed period (e.g., 1 year) as recruitment period for baseline information (e.g., Disease History) and determine a follow-up period for outcomes
B5: Tab No.1 | C5: Codebook
B6: This list contains the definitions of variables in GEM model.
B7: 1) Data Input Table
B8: This table contains definitions of all variables in order to run person-level simulation.
B9: Extracted information for study samples should be provided in Tab No.2 DataInput
B10: It is recommended that researchers try their best to gather information on as many variables as possible.
B11: 2) Baseline Person Level Data
B12: This table contains definitions of the person-level variables derived from Tab No.2 DataInput
B13: 3) Outcomes Table
B14: This table contains definitions of outcome variables
B15: Tab No.2 | C15: DataInput
B16: This is a standard table for input data preparation
B17: Researchers should gather input data for each individual
B18: This table contains one example of study data, which is only used to guide data preparation process.
B19: Tab No.3 | C19: BaselinePersonLevel
B20: This is a standard table for the simulated person-level data
B21: The model takes information from the "DataInput" tab and probabilistically assigns values to each variable in the "BaselinePersonLevel" tab.
B22: This table contains three sample individuals
B23: Tab No.4 | C23: Outcomes
B24: This is a standard table for the projected outcomes
B25: The model takes information from the "DataInput" tab and generates the risk of outcomes in the "Outcomes" tab.
B26: This table also contains three sample individuals

Sheet Codebook
B1: Full Variable List
B2: Variable | C2: Definition | D2: Unit
B3: Data Input
B4: Study ID | C4: Study ID, e.g., trial number with cohort count at end; [trial number]1, [trial number]2
B5: Cohort | C5: Study cohort short definition, e.g., treatment, control, case
B6: Age
B7: Min Age | C7: Minimum age in cohort (used in generating population distribution) | D7: Years
B8: Max Age | C8: Maximum age in cohort | D8: Years
B9: Avg Age | C9: Average age at start of follow-up | D9: Years
B10: SD Age | C10: Standard deviation age at start of follow-up | D10: Years
B11: Female | C11: Proportion female | D11: Rate
B12: ISO3 | C12: Country ISO code (3 letters) | D12: Category
B13: Country Region | C13: Country(ies) in the following WHO Region | D13: 1/0 (Yes/No)
B14: Africa | D14: 1/0 (Yes/No)
B15: Americas | D15: 1/0 (Yes/No)
B16: Eastern Mediterranean | D16: 1/0 (Yes/No)
B17: European | D17: 1/0 (Yes/No)
B18: South-East Asia | D18: 1/0 (Yes/No)
B19: Western Pacific | D19: 1/0 (Yes/No)
B20: Country Income Level | C20: Country(ies) in the following World Bank defined income group
B21: LMIC | C21: Low and Middle Income Countries | D21: 1/0 (Yes/No)
B22: HIC | C22: High Income Countries | D22: 1/0 (Yes/No)
B23: BMI
B24: Min BMI | C24: Minimum BMI in cohort | D24: kg/m2
B25: Max BMI | C25: Maximum BMI in cohort | D25: kg/m2
B26: Avg BMI | C26: Average BMI at start of follow-up | D26: kg/m2
B27: SD BMI | C27: Standard deviation BMI at start of follow-up | D27: kg/m2
B28: Condition Prevalences
B29: Obesity Rate | C29: Obesity (BMI>=30) prevalence rate at start of follow-up | D29: Rate
B30: Class 1 Obesity Rate | C30: Class 1 (BMI 30-34.9) Obesity prevalence rate at start of follow-up | D30: Rate
B31: Class 2 Obesity Rate | C31: Class 2 (BMI 35-39.9) Obesity prevalence rate at start of follow-up | D31: Rate
B32: Class 3 Obesity Rate | C32: Class 3 (BMI >= 40) Obesity prevalence rate at start of follow-up | D32: Rate
B33: T2D Rate | C33: T2D prevalence rate at start of follow-up | D33: Rate
B34: CVD Rate | C34: CVD prevalence rate at start of follow-up | D34: Rate
B35: CKD Rate | C35: CKD prevalence rate at start of follow-up | D35: Rate
B36: ESKD Rate | C36: ESKD prevalence rate at start of follow-up | D36: Rate
B37: Outcomes Cohort Level (Simulated Outcomes and Study Outcomes for Comparison)
B38: Study ID | C38: Study ID, e.g., trial number or count (1,2,3)
B39: Cohort | C39: Study cohort short definition, e.g., treatment, control, case
B40: Unit for Incidence Outcomes | C40: Cumulative or 1-year incidence rate
...

Sheet PersonLevelCodebook
B1: Full Variable List
B2: Variable | D2: Definition | F2: Unit
B3: Data Input
B4: Study ID | D4: Study ID
B5: Min Age | D5: Minimum age in cohort | F5: Years
B6: Max Age | D6: Maximum age in cohort | F6: Years
B7: Avg Age | D7: Average age at start of follow-up | F7: Years
B8: ISO3 | D8: Country ISO code (3 letters) | F8: Category
B9: Country Region | D9: Country(ies) in the following WHO Region | F9: 1/0 (Yes/No)
B10: Africa | F10: 1/0 (Yes/No)
B11: Americas | F11: 1/0 (Yes/No)
B12: Eastern Mediterranean | F12: 1/0 (Yes/No)
B13: European | F13: 1/0 (Yes/No)
B14: South-East Asia | F14: 1/0 (Yes/No)
B15: Western Pacific | F15: 1/0 (Yes/No)
B16: Country Income Level | D16: Country(ies) in the following World Bank defined income group
B17: LMIC | D17: Low and Middle Income Countries | F17: 1/0 (Yes/No)
B18: HIC | D18: High Income Countries | F18: 1/0 (Yes/No)
B19: Min BMI | D19: Minimum BMI in cohort
B20: Max BMI | D20: Maximum BMI in cohort
B21: Avg BMI | D21: Average BMI at start of follow-up
B22: Condition Prevalences
B23: Obesity Rate | D23: Obesity (BMI>=30) prevalence rate at start of follow-up | F23: Rate
B24: Class 1 Obesity Rate | D24: Class 1 (BMI 30-34.9) Obesity prevalence rate at start of follow-up | F24: Rate
B25: Class 2 Obesity Rate | D25: Class 2 (BMI 35-39.9) Obesity prevalence rate at start of follow-up | F25: Rate
B26: Class 3 Obesity Rate | D26: Class 3 (BMI >= 40) Obesity prevalence rate at start of follow-up | F26: Rate
B27: T2D Rate | D27: T2D prevalence rate at start of follow-up | F27: Rate
B28: CVD Rate | D28: CVD prevalence rate at start of follow-up | F28: Rate
B29: CKD Rate | D29: CKD prevalence rate at start of follow-up | F29: Rate
B30: ESKD Rate | D30: ESKD prevalence rate at start of follow-up | F30: Rate
B31: Baseline Person Level Data
B32: PID | D32: Person ID
B33: Age | D33: Age at start of follow-up | F33: Years
B34: Female | D34: Female sex | F34: 1/0 (Yes/No)
B35: ISO3 | D35: Country ISO code (3 letters) | F35: Category
B36: BMI | D36: BMI at start of follow-up | F36: kg/m2
B37: Obesity Baseline | D37: Obesity at start of follow-up | F37: 1/0 (Yes/No)
B38: Class 1 Obesity Baseline | D38: Class 1 (BMI 30-34.9) Obesity at start of follow-up | F38: 1/0 (Yes/No)
B39: Class 2 Obesity Baseline | D39: Class 2 (BMI 35-39.9) Obesity at start of follow-up | F39: 1/0 (Yes/No)
B40: Class 3 Obesity Baseline | D40: Class 3 (BMI >= 40) Obesity at start of follow-up | F40: 1/0 (Yes/No)
...

Sheet Included Study Documentation
A1: Trial Acronym | B1: Study ID | C1: Full Name | D1: Study Type | E1: Chronic Conditions Investigated | F1: Geography | G1: Sample Size | H1: Follow-up Years1 | I1: Link to Referenced Study | J1: Citation
A2: BARI 2D | B2: 1 | C2: A Randomized Trial of Therapies for Type 2 Diabetes and Coronary Artery Disease | D2: RCT | E2: T2D; CVD | F2: MULTI | G2: 2368 | H2: 5.3 | I2: A randomized trial of therapies for type 2 diabetes and coronary artery disease - PubMed | J2: The BARI 2D Study Group. A Randomized Trial of Therapies for Type 2 Diabetes and Coronary Artery Disease. New England Journal of Medicine. 2009;360(24):2503-2515. doi:10.1056/NEJMoa0805796
A3: REWIND | B3: 2 | C3: Dulaglutide and cardiovascular outcomes in type 2 diabetes (REWIND): a double-blind, randomised placebo-controlled trial | D3: RCT | E3: T2D; CVD; STROKE; CKD | F3: MULTI | G3: 9901 | H3: 5.4 | I3: https://www.thelancet.com/journals/lancet/article/PIIS0140-6736(19)31149-3/abstract | J3: Gerstein HC, Colhoun HM, Dagenais GR, et al. Dulaglutide and cardiovascular outcomes in type 2 diabetes (REWIND): a double-blind, randomised placebo-controlled trial. The Lancet. 2019;394(10193):121-130. doi:10.1016/S0140-6736(19)31149-3
A4: look Ahead | B4: 3 | C4: Look AHEAD (Action for Health in Diabetes): Cardiovascular Effects of Intensive Lifestyle Intervention in Type 2 Diabetes | D4: RCT | E4: T2D; CVD | F4: USA | G4: 5145 | H4: 9.6 | I4: Cardiovascular effects of intensive lifestyle intervention in adults with overweight/obesity and type 2 diabetes according to body weight time in range - eClinicalMedicine | J4: Liu M, Huang R, Xu L, et al. Cardiovascular effects of intensive lifestyle intervention in adults with overweight/obesity and type 2 diabetes according to body weight time in range. eClinicalMedicine. 2022;49. doi:10.1016/j.eclinm.2022.101451
A5: Look AHEAD DKD | B5: 4 | C5: Within and post-trial effects of an intensive lifestyle intervention on kidney disease in adults with overweight or obesity and type 2 diabetes | D5: Secondary analysis of multicenter RCT (Look AHEAD) | E5: T2D; CKD; Obesity | F5: USA | G5: 5145 | H5: 15.6 | I5: https://drc.bmj.com/content/12/3/e004079 | J5: Knowler WC, Chen H, Bahnson JL, et al. Within and post-trial effects of an intensive lifestyle intervention on kidney disease in adults with overweight or obesity and type 2 diabetes mellitus: a secondary analysis of the Look AHEAD clinical trial. BMJ Open Diab Res Care. 2024;12(3). doi:10.1136/bmjdrc-2024-004079
A6: ADVANCE-WHR | B6: 5 | C6: Comparison of waist-to-hip ratio and other obesity indices as predictors of cardiovascular disease risk in people with type 2 diabetes: ADVANCE Cohort | D6: Prospective Cohort Subanalysis of ADVANCE Trial | E6: T2D; CVD | F6: MULTI | G6: 11140 | H6: 4.8 | I6: https://pmc.ncbi.nlm.nih.gov/articles/PMC4170784/ | J6: Czernichow S, Kengne AP, Huxley RR, et al. Comparison of waist-to-hip ratio and other obesity indices as predictors of cardiovascular disease risk in people with type 2 diabetes: a prospective cohort study from ADVANCE. Eur J Cardiovasc Prev Rehabil. 2011;18(2):312-319. doi:10.1097/HJR.0b013e32833c1aa3
A7: ADVANCE-ON | B7: 6 | C7: Use of the waist-to-height ratio to predict cardiovascular risk in patients with diabetes: Results from the ADVANCE-ON study | D7: Post-trial observational cohort analysis from ADVANCE trial | E7: T2D; CVD | F7: MULTI | G7: 11125 | H7: 9.0 (mean) | I7: https://dom-pubs.pericles-prod.literatumonline.com/doi/10.1111/dom.13311 | J7: Rådholm K, Chalmers J, Ohkuma T, et al. Use of the waist-to-height ratio to predict cardiovascular risk in patients with diabetes: Results from the ADVANCE-ON study. Diabetes, Obesity and Metabolism. 2018;20(8):1903-1910. doi:10.1111/dom.13311
A8: T2D Subgroups | B8: 7 | C8: Type 2 Diabetes Subgroups, Risk for Complications, and Differential Effects Due to an Intensive Lifestyle Intervention | D8: Secondary analysis of RCT (Look AHEAD trial) | E8: T2D; CVD; Obesity | F8: USA | G8: 5145 | H8: 9.4 | I8: https://diabetesjournals.org/care/article/44/5/1203/138756/Type-2-Diabetes-Subgroups-Risk-for-Complications | J8: Bancks MP, Chen H, Balasubramanyam A, et al. Type 2 Diabetes Subgroups, Risk for Complications, and Differential Effects Due to an Intensive Lifestyle Intervention. Diabetes Care. 2021;44(5):1203-1210. doi:10.2337/dc20-2372
A9: DAPA-CKD | B9: 8 | C9: Quételet (body mass) index and effects of dapagliflozin in chronic kidney disease | D9: Secondary analysis of RCT (DAPA-CKD trial) | E9: CKD; T2D | F9: MULTI | G9: 4304 | H9: 2.4 | I9: https://dom-pubs.pericles-prod.literatumonline.com/doi/10.1111/dom.14641 | J9: Chertow GM, Vart P, Jongs N, et al. Quételet (body mass) index and effects of dapagliflozin in chronic kidney disease. Diabetes, Obesity and Metabolism. 2022;24(5):827-837. doi:10.1111/dom.14641
A12: Notes:
A13: 1 | B13: Median unless noted

Sheet DataInput
A1: Study ID | B1: Cohort | C1: Cohort ID | D1: Unique cohort baseline | E1: Sample size | F1: Follow-up Years | G1: Female | H1: Min Age | I1: Max Age | J1: Avg Age | K1: SD Age | L1: ISO3 | M1: Africa | N1: Americas | O1: Eastern Mediterranean | P1: European | Q1: South-East Asia | R1: Western Pacific | S1: LMIC | T1: HIC | U1: Min BMI | V1: Max BMI | W1: Avg BMI | X1: SD BMI | Y1: Obesity Rate | Z1: Class 1 Obesity Rate | AA1: Class 2 Obesity Rate | AB1: Class 3 Obesity Rate | AC1: T2D Rate | AD1: CVD Rate | AE1: CKD Rate | AF1: ESKD Rate | AG1: Treatment HR1 | AH1: HR1 Outcome | AI1: Treatment HR2 | AJ1: HR2 Outcome | AK1: Treatment HR3 | AL1: HR3 Outcome
A2: 1 | B2: Insulin sensitization & Revasc | C2: 1 | D2: F | E2: =VLOOKUP(A2,'Included Study Documentation'!$B$1:$H$9, 6, FALSE) -> 2368 | F2: 5.3 | G2: =1-0.704 -> 0.296 | H2: 34 | I2: 80 | J2: 62.4 | K2: 8.9 | L2: MULTI | M2: 0 | N2: 1 | O2: 0 | P2: 1 | Q2: 1 | R2: 0 | S2: 1 | T2: 1 | U2: 19 | V2: 50 | W2: 31.3 | X2: 5.9 | Y2: =56.4/100 -> 0.564 | Z2: 0.3 | AA2: 0.17 | AB2: 0.09 | AC2: 1 | AD2: 1 | AE2: 0.29 | AG2: 0.91 | AH2: All cause mortality | AI2: 0.84 | AJ2: MACE
A3: 1 | B3: Insulin provision & revasc | C3: 2 | D3: F | E3: =VLOOKUP(A3,'Included Study Documentation'!$B$1:$H$9, 6, FALSE) -> 2368 | F3: 5.3 | G3: =1-0.704 -> 0.296 | H3: 34 | I3: 80 | J3: 62.4 | K3: 8.9 | L3: MULTI | M3: 0 | N3: 1 | O3: 0 | P3: 1 | Q3: 1 | R3: 0 | S3: 1 | T3: 1 | U3: 19 | V3: 50 | W3: 31.3 | X3: 5.9 | Y3: =56.4/100 -> 0.564 | Z3: 0.3 | AA3: 0.17 | AB3: 0.09 | AC3: 1 | AD3: 1 | AE3: 0.29 | AG3: 1.01 | AH3: All cause mortality | AI3: 1.04 | AJ3: MACE
A4: 1 | B4: Insulin sensitization &Medical Therapy (control) | C4: 3 | D4: F | E4: =VLOOKUP(A4,'Included Study Documentation'!$B$1:$H$9, 6, FALSE) -> 2368 | F4: 5.3 | G4: =1-0.704 -> 0.296 | H4: 34 | I4: 80 | J4: 62.4 | K4: 8.9 | L4: MULTI | M4: 0 | N4: 1 | O4: 0 | P4: 1 | Q4: 1 | R4: 0 | S4: 1 | T4: 1 | U4: 19 | V4: 50 | W4: 31.3 | X4: 5.9 | Y4: =56.4/100 -> 0.564 | Z4: 0.3 | AA4: 0.17 | AB4: 0.09 | AC4: 1 | AD4: 1 | AE4: 0.29
A5: 1 | B5: Insulin provision & medical therapy (control) | C5: 4 | D5: F | E5: =VLOOKUP(A5,'Included Study Documentation'!$B$1:$H$9, 6, FALSE) -> 2368 | F5: 5.3 | G5: =1-0.704 -> 0.296 | H5: 34 | I5: 80 | J5: 62.4 | K5: 8.9 | L5: MULTI | M5: 0 | N5: 1 | O5: 0 | P5: 1 | Q5: 1 | R5: 0 | S5: 1 | T5: 1 | U5: 19 | V5: 50 | W5: 31.3 | X5: 5.9 | Y5: =56.4/100 -> 0.564 | Z5: 0.3 | AA5: 0.17 | AB5: 0.09 | AC5: 1 | AD5: 1 | AE5: 0.29
A6: 2 | B6: REWIND (Dulaglutide-Treatment) | C6: 1 | D6: F | E6: =VLOOKUP(A6,'Included Study Documentation'!$B$1:$H$9, 6, FALSE) -> 9901 | F6: 5.4 | G6: 0.463 | H6: 50 | I6: 85 | J6: 66.2 | K6: 6.5 | L6: MULTI | M6: 1 | N6: 1 | O6: 1 | P6: 1 | Q6: 1 | R6: 1 | S6: 1 | T6: 1 | U6: 23 | V6: 49 | W6: 32.3 | X6: 5.8 | Y6: 0.56 | Z6: 0.33 | AA6: 0.17 | AB6: 0.06 | AC6: 1 | AD6: 0.315 | AE6: 0.222 | AG6: 0.9 | AH6: All cause mortality | AI6: 0.88 | AJ6: MACE
A7: 2 | B7: REWIND (Placebo-Treatment) | C7: 2 | D7: F | E7: =VLOOKUP(A7,'Included Study Documentation'!$B$1:$H$9, 6, FALSE) -> 9901 | F7: 5.4 | G7: 0.463 | H7: 50 | I7: 85 | J7: 66.2 | K7: 6.5 | L7: MULTI | M7: 1 | N7: 1 | O7: 1 | P7: 1 | Q7: 1 | R7: 1 | S7: 1 | T7: 1 | U7: 23 | V7: 49 | W7: 32.3 | X7: 5.8 | Y7: 0.56 | Z7: 0.33 | AA7: 0.17 | AB7: 0.06 | AC7: 1 | AD7: 0.315 | AE7: 0.222
A8: 3 | B8: look Ahead (Treatment) | C8: 1 | D8: F | E8: =VLOOKUP(A8,'Included Study Documentation'!$B$1:$H$9, 6, FALSE) -> 5145 | F8: 9.6 | G8: 0.604 | H8: 45 | I8: 75 | J8: 58.7 | K8: 6.7 | L8: USA | M8: 0 | N8: 1 | O8: 0 | P8: 0 | Q8: 0 | R8: 0 | S8: 0 | T8: 1 | U8: 25 | V8: 50 | W8: 36 | X8: 5.9 | Y8: 1 | AC8: 1 | AD8: 0.139 | AG8: 0.85 | AH8: All cause mortality | AI8: 0.95 | AJ8: MACE
A9: 3 | B9: look Ahead (control) | C9: 2 | D9: F | E9: =VLOOKUP(A9,'Included Study Documentation'!$B$1:$H$9, 6, FALSE) -> 5145 | F9: 9.6 | G9: 0.604 | H9: 45 | I9: 75 | J9: 58.7 | K9: 6.7 | L9: USA | M9: 0 | N9: 1 | O9: 0 | P9: 0 | Q9: 0 | R9: 0 | S9: 0 | T9: 1 | U9: 25 | V9: 50 | W9: 36 | X9: 5.9 | Y9: 1 | AC9: 1 | AD9: 0.139 | AG9: 1 | AH9: All cause mortality | AI9: 1
A10: 4 | B10: Subgroup A age 60 and less Treatment | C10: 1 | D10: T | E10: =VLOOKUP(A10,'Included Study Documentation'!$B$1:$H$9, 6, FALSE) -> 5145 | F10: 15.6 | G10: 0.641 | H10: 45 | I10: 59 | J10: 53.9 | K10: 4.1 | L10: USA | M10: 0 | N10: 1 | O10: 0 | P10: 0 | Q10: 0 | R10: 0 | S10: 0 | T10: 1 | U10: 25 | V10: 51 | W10: 36.6 | X10: 6.3 | Y10: 1 | Z10: 0.33 | AA10: 0.36 | AB10: 0.31 | AC10: 1 | AD10: 0.09 | AE10: 0.1 | AF10: 0.004 | AG10: 0.94 | AH10: CKD
A11: 4 | B11: Subgroup A Comparison/control | C11: 2 | D11: T | E11: =VLOOKUP(A11,'Included Study Documentation'!$B$1:$H$9, 6, FALSE) -> 5145 | F11: 15.6 | G11: 0.647 | H11: 45 | I11: 59 | J11: 54 | K11: 4.1 | L11: USA | M11: 0 | N11: 1 | O11: 0 | P11: 0 | Q11: 0 | R11: 0 | S11: 0 | T11: 1 | U11: 25 | V11: 51 | W11: 36.8 | X11: 6 | Y11: 1 | Z11: 0.35 | AA11: 0.34 | AB11: 0.31 | AC11: 1 | AD11: 0.08 | AE11: 0.1 | AF11: 0.003
A12: 4 | B12: Subgroup B 60 and more Treatment | C12: 3 | D12: T | E12: =VLOOKUP(A12,'Included Study Documentation'!$B$1:$H$9, 6, FALSE) -> 5145 | F12: 15.6 | G12: 0.53 | H12: 60 | I12: 76 | J12: 64.9 | K12: 4 | L12: USA | M12: 0 | N12: 1 | O12: 0 | P12: 0 | Q12: 0 | R12: 0 | S12: 0 | T12: 1 | U12: 25 | V12: 51 | W12: 34.9 | X12: 5.5 | Y12: 1 | Z12: 0.34 | AA12: 0.32 | AB12: 0.34 | AC12: 1 | AD12: 0.21 | AE12: 0.18 | AF12: 0.015 | AG12: 0.81 | AH12: CKD
A13: 4 | B13: Subgroup B Comparison/control | C13: 4 | D13: T | E13: =VLOOKUP(A13,'Included Study Documentation'!$B$1:$H$9, 6, FALSE) -> 5145 | F13: 15.6 | G13: 0.532 | H13: 60 | I13: 76 | J13: 65.2 | K13: 4 | L13: USA | M13: 0 | N13: 1 | O13: 0 | P13: 0 | Q13: 0 | R13: 0 | S13: 0 | T13: 1 | U13: 25 | V13: 51 | W13: 34.9 | X13: 5.2 | Y13: 1 | Z13: 0.36 | AA13: 0.31 | AB13: 0.33 | AC13: 1 | AD13: 0.2 | AE13: 0.19 | AF13: 0.021
A14: 5 | B14: Waist to hip ratio | C14: 1 | D14: T | E14: =VLOOKUP(A14,'Included Study Documentation'!$B$1:$H$9, 6, FALSE) -> 11140 | F14: 4.8 | G14: 0.425 | H14: 30 | I14: 85 | J14: 65.8 | K14: 6.4 | L14: MULTI | M14: 1 | N14: 1 | O14: 1 | P14: 1 | Q14: 1 | R14: 1 | S14: 1 | T14: 1 | U14: 18 | V14: 45 | W14: 28 | X14: 5 | AC14: 1 | AD14: 0.32
A15: 6 | B15: Waist to height ratio study | C15: 1 | D15: T | E15: =VLOOKUP(A15,'Included Study Documentation'!$B$1:$H$9, 6, FALSE) -> 11125 | F15: 9 | G15: 0.42 | H15: 55 | I15: 80 | J15: 66 | K15: 6 | L15: MULTI | M15: 0 | N15: 1 | O15: 0 | P15: 1 | Q15: 1 | R15: 0 | S15: 1 | T15: 1 | U15: 19 | V15: 50 | W15: 31.3 | X15: 5.9 | Y15: 0.56 | Z15: 0.3 | AA15: 0.17 | AB15: 0.09 | AC15: 1 | AD15: 0.32 | AE15: 0.29
A16: 7 | B16: T2D Subgroups Older-Onset (Treatment) | C16: 1 | D16: T | E16: =VLOOKUP(A16,'Included Study Documentation'!$B$1:$H$9, 6, FALSE) -> 5145 | F16: 9.4 | G16: 0.57 | H16: 45 | I16: 76 | J16: 62.1 | K16: 5.7 | L16: USA | M16: 0 | N16: 1 | O16: 0 | P16: 0 | Q16: 0 | R16: 0 | S16: 0 | T16: 1 | U16: 25 | V16: 40 | W16: 33 | X16: 3.5 | Y16: 1 | Z16: 1 | AA16: 0.15 | AC16: 1 | AG16: 0.9 | AH16: MACE
A17: 7 | B17: Poor Control (treatment) | C17: 2 | D17: T | E17: =VLOOKUP(A17,'Included Study Documentation'!$B$1:$H$9, 6, FALSE) -> 5145 | F17: 9.4 | G17: 0.59 | H17: 45 | I17: 76 | J17: 57 | K17: 6.2 | L17: USA | M17: 0 | N17: 1 | O17: 0 | P17: 0 | Q17: 0 | R17: 0 | S17: 0 | T17: 1 | U17: 30 | V17: 45 | W17: 35.7 | X17: 4.4 | Y17: 1 | Z17: 1 | AA17: 0.14 | AC17: 1 | AG17: 1.85 | AH17: MACE
A18: 7 | B18: Severe Obesity (treatment) | C18: 3 | D18: T | E18: =VLOOKUP(A18,'Included Study Documentation'!$B$1:$H$9, 6, FALSE) -> 5145 | F18: 9.4 | G18: 0.61 | H18: 45 | I18: 76 | J18: 57.2 | K18: 6.4 | L18: USA | M18: 0 | N18: 1 | O18: 0 | P18: 0 | Q18: 0 | R18: 0 | S18: 0 | T18: 1 | U18: 40 | V18: 55 | W18: 43.6 | X18: 4.6 | Y18: 1 | Z18: 1 | AA18: 0.12 | AC18: 1 | AG18: 0.78 | AH18: MACE
A19: 7 | B19: Younger-Onset (treatment) | C19: 4 | D19: T | E19: =VLOOKUP(A19,'Included Study Documentation'!$B$1:$H$9, 6, FALSE) -> 5145 | F19: 9.4 | G19: 0.64 | H19: 45 | I19: 76 | J19: 54.5 | K19: 6.4 | L19: USA | M19: 0 | N19: 1 | O19: 0 | P19: 0 | Q19: 0 | R19: 0 | S19: 0 | T19: 1 | U19: 27 | V19: 40 | W19: 33.3 | X19: 3.7 | Y19: 1 | Z19: 1 | AA19: 0.13 | AC19: 1 | AG19: 0.82 | AH19: MACE
A20: 7 | B20: T2D Subgroups Older-Onset (control) | C20: 5 | D20: T | E20: =VLOOKUP(A20,'Included Study Documentation'!$B$1:$H$9, 6, FALSE) -> 5145 | F20: 9.4 | G20: 0.57 | H20: 45 | I20: 76 | J20: 62.1 | K20: 5.7 | L20: USA | M20: 0 | N20: 1 | O20: 0 | P20: 0 | Q20: 0 | R20: 0 | S20: 0 | T20: 1 | U20: 25 | V20: 40 | W20: 33 | X20: 3.5 | Y20: 1 | Z20: 1 | AA20: 0.15 | AC20: 1
A21: 7 | B21: Poor Control (control) | C21: 6 | D21: T | E21: =VLOOKUP(A21,'Included Study Documentation'!$B$1:$H$9, 6, FALSE) -> 5145 | F21: 9.4 | G21: 0.59 | H21: 45 | I21: 76 | J21: 57 | K21: 6.2 | L21: USA | M21: 0 | N21: 1 | O21: 0 | P21: 0 | Q21: 0 | R21: 0 | S21: 0 | T21: 1 | U21: 30 | V21: 45 | W21: 35.7 | X21: 4.4 | Y21: 1 | Z21: 1 | AA21: 0.14 | AC21: 1
A22: 7 | B22: Severe Obesity (control) | C22: 7 | D22: T | E22: =VLOOKUP(A22,'Included Study Documentation'!$B$1:$H$9, 6, FALSE) -> 5145 | F22: 9.4 | G22: 0.61 | H22: 45 | I22: 76 | J22: 57.2 | K22: 6.4 | L22: USA | M22: 0 | N22: 1 | O22: 0 | P22: 0 | Q22: 0 | R22: 0 | S22: 0 | T22: 1 | U22: 40 | V22: 55 | W22: 43.6 | X22: 4.6 | Y22: 1 | Z22: 1 | AA22: 0.12 | AC22: 1
A23: 7 | B23: Younger-Onset (control) | C23: 8 | D23: T | E23: =VLOOKUP(A23,'Included Study Documentation'!$B$1:$H$9, 6, FALSE) -> 5145 | F23: 9.4 | G23: 0.64 | H23: 45 | I23: 76 | J23: 54.5 | K23: 6.4 | L23: USA | M23: 0 | N23: 1 | O23: 0 | P23: 0 | Q23: 0 | R23: 0 | S23: 0 | T23: 1 | U23: 27 | V23: 40 | W23: 33.3 | X23: 3.7 | Y23: 1 | Z23: 1 | AA23: 0.13 | AC23: 1
A24: 8 | B24: Lean/Ideal-Treatment | C24: 1 | D24: T | E24: =VLOOKUP(A24,'Included Study Documentation'!$B$1:$H$9, 6, FALSE) -> 4304 | F24: 2.4 | G24: 0.384 | H24: 18 | I24: 25 | J24: 58.6 | K24: 14.4 | L24: MULTI | M24: 1 | N24: 1 | O24: 0 | P24: 1 | Q24: 0 | R24: 1 | S24: 1 | T24: 1 | U24: 18 | V24: 24.9 | W24: 22.2 | X24: 1.7 | Y24: 0 | Z24: 0 | AA24: 0 | AB24: 0 | AC24: 0.56 | AD24: 0.28 | AE24: 1 | AF24: 0.03 | AG24: 0.55 | AH24: ESKD | AI24: 0.88 | AJ24: CVD | AK24: 0.78 | AL24: All cause mortality
A25: 8 | B25: Overweight-Treatment | C25: 2 | D25: T | E25: =VLOOKUP(A25,'Included Study Documentation'!$B$1:$H$9, 6, FALSE) -> 4304 | F25: 2.4 | G25: 0.277 | H25: 25 | I25: 30 | J25: 62.5 | K25: 12 | L25: MULTI | M25: 1 | N25: 1 | O25: 0 | P25: 1 | Q25: 0 | R25: 1 | S25: 1 | T25: 1 | U25: 25 | V25: 29.9 | W25: 27 | X25: 1.4 | Y25: 0 | AC25: 0.64 | AD25: 0.33 | AE25: 1 | AF25: 0.04 | AG25: 0.54 | AH25: ESKD | AI25: 0.72 | AJ25: CVD | AK25: 0.51 | AL25: All cause mortality
A26: 8 | B26: Grade 1 Obesity-Treatment | C26: 3 | D26: T | E26: =VLOOKUP(A26,'Included Study Documentation'!$B$1:$H$9, 6, FALSE) -> 4304 | F26: 2.4 | G26: 0.328 | H26: 30 | I26: 35 | J26: 63 | K26: 10.8 | L26: MULTI | M26: 1 | N26: 1 | O26: 0 | P26: 1 | Q26: 0 | R26: 1 | S26: 1 | T26: 1 | U26: 30 | V26: 34.9 | W26: 31.7 | X26: 1.4 | Y26: 1 | Z26: 1 | AA26: 0 | AB26: 0 | AC26: 0.72 | AD26: 0.44 | AE26: 1 | AF26: 0.05 | AG26: 0.51 | AH26: ESKD | AI26: 0.94 | AJ26: CVD | AK26: 0.98 | AL26: All cause mortality
A27: 8 | B27: Grade 2/3 Obesity-Treatment | C27: 4 | D27: T | E27: =VLOOKUP(A27,'Included Study Documentation'!$B$1:$H$9, 6, FALSE) -> 4304 | F27: 2.4 | G27: 0.376 | H27: 35 | I27: 45 | J27: 62.2 | K27: 10.7 | L27: MULTI | M27: 1 | N27: 1 | O27: 0 | P27: 1 | Q27: 0 | R27: 1 | S27: 1 | T27: 1 | U27: 35 | V27: 45 | W27: 39.4 | X27: 4.7 | Y27: 1 | Z27: 0 | AC27: 0.83 | AD27: 0.46 | AE27: 1 | AF27: 0.06 | AG27: 0.6 | AH27: ESKD | AI27: 0.46 | AJ27: CVD | AK27: 0.65 | AL27: All cause mortality
A28: 8 | B28: Lean/Ideal-Control | C28: 5 | D28: T | E28: =VLOOKUP(A28,'Included Study Documentation'!$B$1:$H$9, 6, FALSE) -> 4304 | F28: 2.4 | G28: 0.375 | H28: 18 | I28: 25 | J28: 58.6 | K28: 14.4 | L28: MULTI | M28: 1 | N28: 1 | O28: 0 | P28: 1 | Q28: 0 | R28: 1 | S28: 1 | T28: 1 | U28: 18 | V28: 24.9 | W28: 22.2 | X28: 1.7 | Y28: 0 | Z28: 0 | AA28: 0 | AB28: 0 | AC28: 0.56 | AD28: 0.28 | AE28: 1 | AF28: 0.03
A29: 8 | B29: Overweight-Control | C29: 6 | D29: T | E29: =VLOOKUP(A29,'Included Study Documentation'!$B$1:$H$9, 6, FALSE) -> 4304 | F29: 2.4 | G29: 0.297 | H29: 25 | I29: 30 | J29: 62.5 | K29: 12 | L29: MULTI | M29: 1 | N29: 1 | O29: 0 | P29: 1 | Q29: 0 | R29: 1 | S29: 1 | T29: 1 | U29: 25 | V29: 29.9 | W29: 27 | X29: 1.4 | Y29: 0 | AC29: 0.64 | AD29: 0.33 | AE29: 1 | AF29: 0.04
A30: 8 | B30: Grade 1 Obesity-Control | C30: 7 | D30: T | E30: =VLOOKUP(A30,'Included Study Documentation'!$B$1:$H$9, 6, FALSE) -> 4304 | F30: 2.4 | G30: 0.312 | H30: 30 | I30: 35 | J30: 63 | K30: 10.8 | L30: MULTI | M30: 1 | N30: 1 | O30: 0 | P30: 1 | Q30: 0 | R30: 1 | S30: 1 | T30: 1 | U30: 30 | V30: 34.9 | W30: 31.7 | X30: 1.4 | Y30: 1 | Z30: 1 | AA30: 0 | AB30: 0 | AC30: 0.72 | AD30: 0.44 | AE30: 1 | AF30: 0.05
A31: 8 | B31: Grade 2/3 Obesity-Control | C31: 8 | D31: T | E31: =VLOOKUP(A31,'Included Study Documentation'!$B$1:$H$9, 6, FALSE) -> 4304 | F31: 2.4 | G31: 0.377 | H31: 35 | I31: 45 | J31: 62.2 | K31: 10.7 | L31: MULTI | M31: 1 | N31: 1 | O31: 0 | P31: 1 | Q31: 0 | R31: 1 | S31: 1 | T31: 1 | U31: 35 | V31: 45 | W31: 39.4 | X31: 4.7 | Y31: 1 | Z31: 0 | AC31: 0.83 | AD31: 0.46 | AE31: 1 | AF31: 0.06

Sheet ComparisonOutcomes
A1: Study ID | B1: Cohort ID | C1: Cohort | D1: Incidence time unit | E1: Stroke | F1: Death | G1: MACE | H1: New CKD | I1: New CVD | J1: New ESKD | K1: New T2D
A2: 1 | B2: 1 | C2: Insulin sensitization & Revasc (treatment) | D2: cumulative | F2: 0.112 | G2: 0.2
A3: 1 | B3: 2 | C3: Insulin sensitization &Medical Therapy (control) | D3: cumulative | F3: 0.123 | G3: 0.241
A4: 1 | B4: 3 | C4: Insulin provision & revasc (treatment) | D4: cumulative | F4: 0.122 | G4: 0.252
A5: 1 | B5: 4 | C5: Insulin provision & medical therapy (control) | D5: cumulative | F5: 0.12 | G5: 0.24
A6: 2 | B6: 1 | C6: Dulaglutide | D6: 1 year | G6: =2.4/100 -> 0.024
A7: 2 | B7: 2 | C7: Placebo | D7: 1 year | G7: =2.7/100 -> 0.027
A8: 3 | B8: 1 | C8: Look Ahead Intervention | D8: 1 year | E8: =0.36/100 -> 0.0036 | F8: =0.24/100 -> 0.0024 | G8: =1.83/100 -> 0.0183
A9: 3 | B9: 2 | C9: look Ahead Control | D9: 1 year | E9: =0.34/100 -> 0.0034 | F9: =0.86/100 -> 0.0086 | G9: =1.92/100 -> 0.0192
A10: 4 | B10: 1 | C10: Subgroup A age 60 and less Treatment | D10: 1 year | J10: =2.4/100 -> 0.024
A11: 4 | B11: 2 | C11: Subgroup A Comparison/control | D11: 1 year | J11: =2.23/100 -> 0.0223
A12: 4 | B12: 3 | C12: Subgroup B 60 and more Treatment | D12: 1 year | J12: =1.8/100 -> 0.018
A13: 4 | B13: 4 | C13: Subgroup B Comparison/control | D13: 1 year | J13: =2.35/100 -> 0.0235
A14: 5 | B14: 1 | C14: Waist to hip ratio | D14: cumulative | E14: 0.043 | F14: 0.049 | I14: 0.103
A15: 6 | B15: 1 | C15: Waist to hip ratio | D15: cumulative | E15: 0.087 | F15: 0.203 | I15: 0.065
A16: 7 | B16: 1 | C16: Older onset (treatment) | D16: 1 year | G16: =11.5/1000 -> 0.0115
A17: 7 | B17: 2 | C17: Older onset (control) | D17: 1 year | G17: =13.1/1000 -> 0.0131
A18: 7 | B18: 3 | C18: Poor glucose control (treatment) | D18: 1 year | G18: =19.2/1000 -> 0.0192
A19: 7 | B19: 4 | C19: Poor glucose control (control) | D19: 1 year | G19: =13.6/1000 -> 0.0136
A20: 7 | B20: 5 | C20: Severe obesity (treatment) | D20: 1 year | G20: =10.5/1000 -> 0.0105
A21: 7 | B21: 6 | C21: Severe Obesity (control) | D21: 1 year | G21: =12.5/1000 -> 0.0125
A22: 7 | B22: 7 | C22: Younger onset (treatment) | D22: 1 year | G22: =9/1000 -> 0.009
A23: 7 | B23: 8 | C23: Younger onset (control) | D23: 1 year | G23: =10.7/1000 -> 0.0107
A24: 8 | B24: 1 | C24: Lean/Ideal-Treatment | D24: cumulative | F24: =2.2/100 -> 0.022 | G24: =1.7/100 -> 0.017 | J24: =5.6/100 -> 0.056
A25: 8 | B25: 2 | C25: Overweight-Treatment | D25: cumulative | F25: =2/100 -> 0.02 | G25: =1.7/100 -> 0.017 | J25: =3/100 -> 0.03
A26: 8 | B26: 3 | C26: Grade 1 Obesity-Treatment | D26: cumulative | F26: =2.4/100 -> 0.024 | G26: =2.9/100 -> 0.029 | J26: =2.1/100 -> 0.021
A27: 8 | B27: 4 | C27: Grade 2/3 Obesity-Treatment | D27: cumulative | F27: =2.1/100 -> 0.021 | G27: =2.4/100 -> 0.024 | J27: =3.2/100 -> 0.032
A28: 8 | B28: 5 | C28: Lean/Ideal-Control | D28: cumulative | F28: =2.9/100 -> 0.029 | G28: =2/100 -> 0.02 | J28: =9.4/100 -> 0.094
A29: 8 | B29: 6 | C29: Overweight-Control | D29: cumulative | F29: =3.8/100 -> 0.038 | G29: =2.3/100 -> 0.023 | J29: =5.6/100 -> 0.056
A30: 8 | B30: 7 | C30: Grade 1 Obesity-Control | D30: cumulative | F30: =2.5/100 -> 0.025 | G30: =3.2/100 -> 0.032 | J30: =4.2/100 -> 0.042
A31: 8 | B31: 8 | C31: Grade 2/3 Obesity-Control | D31: cumulative | F31: =3.2/100 -> 0.032 | G31: =4.9/100 -> 0.049 | J31: =5/100 -> 0.05

Sheet SimOutcomes
A1: Study ID | B1: Cohort | C1: Stroke | D1: Death | E1: New CKD | F1: New CVD | G1: New ESKD | H1: New T2D | I1: Obesity Rate End | J1: Class 1 Obesity Rate End | K1: Class 2 Obesity Rate End | L1: Class 3 Obesity Rate End

Sheet BaselinePersonLevel
A1: PID | B1: Age | C1: Female | D1: ISO3 | E1: BMI | F1: Obesity Baseline | G1: Class 1 Obesity Baseline | H1: Class 2 Obesity Baseline | I1: Class 3 Obesity Baseline | J1: T2D | K1: CVD | L1: CKD | M1: ESKD
A2: 121101 | B2: 18 | C2: 0 | D2: USA | E2: 34 | F2: 1 | G2: 1 | H2: 0 | I2: 0 | J2: 1 | K2: 0 | L2: 0 | M2: 0
A3: 121102 | B3: 45 | C3: 1 | D3: USA | E3: 38 | F3: 1 | G3: 0 | H3: 1 | I3: 0 | J3: 0 | K3: 1 | L3: 0 | M3: 0
A4: 121103 | B4: 65 | C4: 1 | D4: USA | E4: 20 | F4: 0 | G4: 0 | H4: 0 | I4: 0 | J4: 1 | K4: 1 | L4: 1 | M4: 0

Sheet OutcomesPersonLevel
A1: PID | B1: Stroke | C1: ESKD | D1: New CKD | E1: New CVD | F1: New T2D | G1: Death | H1: Obesity | I1: Class 1 Obesity | J1: Class 2 Obesity | K1: Class 3 Obesity
A2: 121101 | B2: 0 | C2: 0 | D2: 0 | E2: 1 | F2: 0 | G2: 0 | H2: 1 | I2: 0 | J2: 1 | K2: 0
A3: 121102 | B3: 0 | C3: 0 | D3: 1 | E3: 0 | F3: 1 | G3: 0 | H3: 1 | I3: 0 | J3: 0 | K3: 1
A4: 121103 | B4: 1 | C4: 0 | D4: 0 | E4: 0 | F4: 0 | G4: 1 | H4: 0 | I4: 0 | J4: 0 | K4: 0
